2013-08-10 20:21:36,091 - mylog - ERROR - 'str' object has no attribute 'read'
2013-08-10 20:41:13,473 - mylog - ERROR - 'str' object has no attribute 'read'
2013-08-11 19:25:52,119 - mylog - ERROR - (1062, "Duplicate entry 'qr-THEOLDREADER' for key 'PRIMARY'")
2013-08-11 19:54:54,238 - mylog - ERROR - (1062, "Duplicate entry 'qr2434061@gmail.com-theoldreader' for key 'PRIMARY'")
2013-08-11 20:06:03,862 - mylog - ERROR - (1062, "Duplicate entry 'qr2434061@gmail.com-theoldreader' for key 'PRIMARY'")
2013-08-11 20:14:20,782 - mylog - ERROR - (1062, "Duplicate entry 'qr2434061@gmail.com-theoldreader' for key 'PRIMARY'")
2013-08-11 20:15:13,296 - mylog - ERROR - (1062, "Duplicate entry 'qr2434061@gmail.com-theoldreader' for key 'PRIMARY'")
2013-08-11 20:15:53,304 - mylog - ERROR - (1062, "Duplicate entry 'qr2434061@gmail.com-theoldreader' for key 'PRIMARY'")
2013-08-11 20:16:40,927 - mylog - ERROR - (1062, "Duplicate entry 'qr2434061@gmail.com-theoldreader' for key 'PRIMARY'")
2013-08-11 20:17:36,655 - mylog - ERROR - (1062, "Duplicate entry 'qr2434061@gmail.com-theoldreader' for key 'PRIMARY'")
2013-08-11 20:21:25,014 - mylog - ERROR - (1062, "Duplicate entry 'qr2434061@gmail.com-theoldreader' for key 'PRIMARY'")
2013-08-11 20:48:10,173 - mylog - ERROR - expected string or buffer
2013-08-12 21:00:32,418 - mylog - ERROR - expected string or buffer
2013-08-12 21:14:22,637 - mylog - ERROR - Module: theoldreaderRss    Function: loginWithCurl
expected string or buffer
2013-08-12 21:16:15,164 - mylog - ERROR - Module: theoldreaderRss    Function: loginWithCurl
expected string or buffer
2013-08-12 21:18:33,571 - mylog - ERROR - Module: theoldreaderRss    Function: loginWithCurl

2013-08-12 21:18:33,571 - mylog - ERROR - Module: theoldreaderRss    Function: loginWithCurl

2013-08-12 21:26:20,702 - mylog - ERROR - (1064, "You have an error in your SQL syntax; check the manual that corresponds to your MySQL server version for the right syntax to use near '@gmail.com and password = theoldreader789456' at line 1")
2013-08-12 21:26:57,080 - mylog - ERROR - (1064, "You have an error in your SQL syntax; check the manual that corresponds to your MySQL server version for the right syntax to use near '@gmail.com and password = theoldreader789456' at line 1")
2013-08-12 21:26:57,082 - mylog - ERROR - (1062, "Duplicate entry 'qr2434061@gmail.com-theoldreader' for key 'PRIMARY'")
2013-08-12 21:26:57,082 - mylog - ERROR - (1062, "Duplicate entry 'qr2434061@gmail.com-theoldreader' for key 'PRIMARY'")
2013-08-12 21:27:56,095 - mylog - ERROR - (1064, "You have an error in your SQL syntax; check the manual that corresponds to your MySQL server version for the right syntax to use near '@gmail.com and password = theoldreader789456' at line 1")
2013-08-12 21:27:56,096 - mylog - ERROR - (1062, "Duplicate entry 'qr2434061@gmail.com-theoldreader' for key 'PRIMARY'")
2013-08-12 21:27:56,096 - mylog - ERROR - (1062, "Duplicate entry 'qr2434061@gmail.com-theoldreader' for key 'PRIMARY'")
2013-08-12 21:38:21,040 - mylog - ERROR - (1064, "You have an error in your SQL syntax; check the manual that corresponds to your MySQL server version for the right syntax to use near '@gmail.com and password = theoldreader789456' at line 1")
2013-08-12 21:38:21,041 - mylog - ERROR - (1062, "Duplicate entry 'qr2434061@gmail.com-theoldreader' for key 'PRIMARY'")
2013-08-12 21:38:21,041 - mylog - ERROR - (1062, "Duplicate entry 'qr2434061@gmail.com-theoldreader' for key 'PRIMARY'")
2013-08-12 21:39:11,381 - mylog - ERROR - (1064, "You have an error in your SQL syntax; check the manual that corresponds to your MySQL server version for the right syntax to use near '@gmail.com and password = theoldreader789456' at line 1")
2013-08-12 21:39:11,382 - mylog - ERROR - (1062, "Duplicate entry 'qr2434061@gmail.com-theoldreader' for key 'PRIMARY'")
2013-08-12 21:39:11,382 - mylog - ERROR - (1062, "Duplicate entry 'qr2434061@gmail.com-theoldreader' for key 'PRIMARY'")
2013-08-12 21:39:48,696 - mylog - ERROR - (1064, "You have an error in your SQL syntax; check the manual that corresponds to your MySQL server version for the right syntax to use near '@gmail.com and password = theoldreader789456' at line 1")
2013-08-12 21:39:48,697 - mylog - ERROR - (1062, "Duplicate entry 'qr2434061@gmail.com-theoldreader' for key 'PRIMARY'")
2013-08-12 21:39:48,697 - mylog - ERROR - (1062, "Duplicate entry 'qr2434061@gmail.com-theoldreader' for key 'PRIMARY'")
2013-08-12 21:59:08,497 - mylog - ERROR - Module: theoldreaderRss    Function: __init__
local variable 'e' referenced before assignment
2013-08-12 23:34:01,032 - mylog - ERROR - (1064, "You have an error in your SQL syntax; check the manual that corresponds to your MySQL server version for the right syntax to use near '@gmail.com and password = theoldreader789456' at line 1")
2013-08-12 23:34:01,033 - mylog - ERROR - (1062, "Duplicate entry 'qr2434061@gmail.com-theoldreader' for key 'PRIMARY'")
2013-08-12 23:34:01,033 - mylog - ERROR - (1062, "Duplicate entry 'qr2434061@gmail.com-theoldreader' for key 'PRIMARY'")
2013-08-12 23:42:18,310 - mylog - ERROR - (1064, "You have an error in your SQL syntax; check the manual that corresponds to your MySQL server version for the right syntax to use near '@gmail.com and password = theoldreader789456' at line 1")
2013-08-12 23:43:36,883 - mylog - ERROR - (1146, "Table 'reader.ProxyAccount' doesn't exist")
2013-08-12 23:43:36,884 - mylog - ERROR - (1062, "Duplicate entry 'qr2434061@gmail.com-theoldreader' for key 'PRIMARY'")
2013-08-12 23:43:36,884 - mylog - ERROR - (1062, "Duplicate entry 'qr2434061@gmail.com-theoldreader' for key 'PRIMARY'")
2013-08-17 16:32:18,314 - mylog - ERROR - (1064, 'You have an error in your SQL syntax; check the manual that corresponds to your MySQL server version for the right syntax to use near \'http://blog.jobbole.com/44175/">\xe5\xa6\x82\xe4\xbd\x95\xe9\x80\x89\xe6\x8b\xa9\xe5\xbc\x80\xe6\xba\x90\xe8\xae\xb8\xe5\x8f\xaf\xe5\x8d\x8f\xe8\xae\xae\xef\xbc\x88\xe4\xb8\x80\xef\xbc\x89\xef\xbc\x9a\xe4\xba\x86\xe8\xa7\xa3\' at line 1')
2013-08-17 16:34:07,344 - mylog - ERROR - (1064, 'You have an error in your SQL syntax; check the manual that corresponds to your MySQL server version for the right syntax to use near \'http://blog.jobbole.com/44175/">\xe5\xa6\x82\xe4\xbd\x95\xe9\x80\x89\xe6\x8b\xa9\xe5\xbc\x80\xe6\xba\x90\xe8\xae\xb8\xe5\x8f\xaf\xe5\x8d\x8f\xe8\xae\xae\xef\xbc\x88\xe4\xb8\x80\xef\xbc\x89\xef\xbc\x9a\xe4\xba\x86\xe8\xa7\xa3\' at line 1')
2013-08-17 16:39:16,849 - mylog - ERROR - (1064, 'You have an error in your SQL syntax; check the manual that corresponds to your MySQL server version for the right syntax to use near \'http://blog.jobbole.com/44175/">\xe5\xa6\x82\xe4\xbd\x95\xe9\x80\x89\xe6\x8b\xa9\xe5\xbc\x80\xe6\xba\x90\xe8\xae\xb8\xe5\x8f\xaf\xe5\x8d\x8f\xe8\xae\xae\xef\xbc\x88\xe4\xb8\x80\xef\xbc\x89\xef\xbc\x9a\xe4\xba\x86\xe8\xa7\xa3\' at line 1')
2013-08-17 19:02:57,090 - mylog - ERROR - (1136, "Column count doesn't match value count at row 1")
2013-08-17 20:18:57,222 - mylog - ERROR - (1062, "Duplicate entry '<built-in function id>' for key 'PRIMARY'")
2013-08-18 10:46:42,206 - mylog - ERROR - (1062, "Duplicate entry '520e866f7c389ce998002ec0' for key 'PRIMARY'")
2013-08-18 10:46:42,541 - mylog - ERROR - (1062, "Duplicate entry '520e2df7eb779f6d58001d04' for key 'PRIMARY'")
2013-08-18 10:46:42,541 - mylog - ERROR - (1062, "Duplicate entry '520e2df7eb779f6d58001d04' for key 'PRIMARY'")
2013-08-18 10:46:42,861 - mylog - ERROR - (1062, "Duplicate entry '520dbc207c389cea0d002730' for key 'PRIMARY'")
2013-08-18 10:46:42,861 - mylog - ERROR - (1062, "Duplicate entry '520dbc207c389cea0d002730' for key 'PRIMARY'")
2013-08-18 10:46:42,861 - mylog - ERROR - (1062, "Duplicate entry '520dbc207c389cea0d002730' for key 'PRIMARY'")
2013-08-20 22:14:57,375 - mylog - ERROR - [Errno 98] Address already in use
2013-08-20 22:37:55,823 - mylog - ERROR - 'str' object has no attribute 'read'
2013-08-20 22:37:55,823 - mylog - ERROR - 'str' object has no attribute 'read'
2013-08-20 22:39:21,980 - mylog - ERROR - 'str' object has no attribute 'read'
2013-08-20 22:39:21,980 - mylog - ERROR - 'str' object has no attribute 'read'
2013-08-20 22:41:31,499 - mylog - ERROR - [Errno 98] Address already in use
2013-08-20 22:42:22,543 - mylog - ERROR - [Errno 98] Address already in use
2013-08-20 22:43:51,028 - mylog - ERROR - 'str' object has no attribute 'read'
2013-08-20 22:43:51,028 - mylog - ERROR - 'str' object has no attribute 'read'
2013-08-20 22:44:28,972 - mylog - ERROR - [Errno 98] Address already in use
2013-08-20 22:50:19,221 - mylog - ERROR - 'str' object has no attribute 'read'
2013-08-20 22:50:19,221 - mylog - ERROR - 'str' object has no attribute 'read'
2013-08-20 22:58:51,379 - mylog - ERROR - [Errno 98] Address already in use
2013-08-20 22:59:16,833 - mylog - ERROR - [Errno 98] Address already in use
2013-08-20 23:01:04,391 - mylog - ERROR - [Errno 98] Address already in use
2013-08-20 23:23:20,808 - mylog - ERROR - 'str' object has no attribute 'read'
2013-08-20 23:23:20,808 - mylog - ERROR - 'str' object has no attribute 'read'
2013-08-20 23:27:40,154 - mylog - ERROR - [Errno 98] Address already in use
2013-08-20 23:28:01,947 - mylog - ERROR - [Errno 98] Address already in use
2013-08-20 23:29:03,206 - mylog - ERROR - 'str' object has no attribute 'read'
2013-08-20 23:29:03,206 - mylog - ERROR - 'str' object has no attribute 'read'
2013-08-20 23:33:32,269 - mylog - ERROR - unsupported operand type(s) for -: 'unicode' and 'int'
2013-08-20 23:33:32,269 - mylog - ERROR - unsupported operand type(s) for -: 'unicode' and 'int'
2013-08-20 23:34:17,004 - mylog - ERROR - unsupported operand type(s) for -: 'unicode' and 'int'
2013-08-20 23:34:17,004 - mylog - ERROR - unsupported operand type(s) for -: 'unicode' and 'int'
2013-08-20 23:34:36,790 - mylog - ERROR - unsupported operand type(s) for -: 'unicode' and 'int'
2013-08-20 23:34:36,790 - mylog - ERROR - unsupported operand type(s) for -: 'unicode' and 'int'
2013-08-20 23:36:23,050 - mylog - ERROR - unsupported operand type(s) for -: 'unicode' and 'int'
2013-08-20 23:36:23,050 - mylog - ERROR - unsupported operand type(s) for -: 'unicode' and 'int'
2013-08-20 23:42:15,728 - mylog - ERROR - unsupported operand type(s) for -: 'unicode' and 'int'
2013-08-20 23:42:15,728 - mylog - ERROR - unsupported operand type(s) for -: 'unicode' and 'int'
2013-08-20 23:43:06,192 - mylog - ERROR - unsupported operand type(s) for -: 'unicode' and 'int'
2013-08-20 23:43:06,192 - mylog - ERROR - unsupported operand type(s) for -: 'unicode' and 'int'
2013-08-20 23:44:18,296 - mylog - ERROR - unsupported operand type(s) for -: 'unicode' and 'int'
2013-08-20 23:44:18,296 - mylog - ERROR - unsupported operand type(s) for -: 'unicode' and 'int'
2013-08-20 23:50:48,480 - mylog - ERROR - Traceback (most recent call last):
  File "/home/asus/code/RecommendedReader/socketServer.py", line 54, in process
    begin = (order - 1) * ITEM_NUMBER_RETURN + 1
TypeError: unsupported operand type(s) for -: 'unicode' and 'int'

2013-08-20 23:50:48,480 - mylog - ERROR - Traceback (most recent call last):
  File "/home/asus/code/RecommendedReader/socketServer.py", line 54, in process
    begin = (order - 1) * ITEM_NUMBER_RETURN + 1
TypeError: unsupported operand type(s) for -: 'unicode' and 'int'

2013-08-20 23:51:26,173 - mylog - ERROR - Traceback (most recent call last):
  File "/home/asus/code/RecommendedReader/socketServer.py", line 54, in process
    begin = (order - 1) * ITEM_NUMBER_RETURN + 1
TypeError: unsupported operand type(s) for -: 'unicode' and 'int'

2013-08-20 23:51:26,173 - mylog - ERROR - Traceback (most recent call last):
  File "/home/asus/code/RecommendedReader/socketServer.py", line 54, in process
    begin = (order - 1) * ITEM_NUMBER_RETURN + 1
TypeError: unsupported operand type(s) for -: 'unicode' and 'int'

2013-08-20 23:52:10,743 - mylog - ERROR - (1064, "You have an error in your SQL syntax; check the manual that corresponds to your MySQL server version for the right syntax to use near '-19,0 order by weight' at line 1")
2013-08-20 23:52:10,743 - mylog - ERROR - (1064, "You have an error in your SQL syntax; check the manual that corresponds to your MySQL server version for the right syntax to use near '-19,0 order by weight' at line 1")
2013-08-20 23:52:10,744 - mylog - ERROR - Traceback (most recent call last):
  File "/home/asus/code/RecommendedReader/socketServer.py", line 70, in process
    rowcount = cursor.rowcount
AttributeError: 'NoneType' object has no attribute 'rowcount'

2013-08-20 23:52:10,744 - mylog - ERROR - Traceback (most recent call last):
  File "/home/asus/code/RecommendedReader/socketServer.py", line 70, in process
    rowcount = cursor.rowcount
AttributeError: 'NoneType' object has no attribute 'rowcount'

2013-08-20 23:52:10,744 - mylog - ERROR - Traceback (most recent call last):
  File "/home/asus/code/RecommendedReader/socketServer.py", line 70, in process
    rowcount = cursor.rowcount
AttributeError: 'NoneType' object has no attribute 'rowcount'

2013-08-21 00:02:33,312 - mylog - ERROR - (1064, "You have an error in your SQL syntax; check the manual that corresponds to your MySQL server version for the right syntax to use near '-19,0 order by weight' at line 1")
2013-08-21 00:02:33,312 - mylog - ERROR - (1064, "You have an error in your SQL syntax; check the manual that corresponds to your MySQL server version for the right syntax to use near '-19,0 order by weight' at line 1")
2013-08-21 00:02:33,313 - mylog - ERROR - Traceback (most recent call last):
  File "/home/asus/code/RecommendedReader/socketServer.py", line 71, in process
    rowcount = cursor.rowcount
AttributeError: 'NoneType' object has no attribute 'rowcount'

2013-08-21 00:02:33,313 - mylog - ERROR - Traceback (most recent call last):
  File "/home/asus/code/RecommendedReader/socketServer.py", line 71, in process
    rowcount = cursor.rowcount
AttributeError: 'NoneType' object has no attribute 'rowcount'

2013-08-21 00:02:33,313 - mylog - ERROR - Traceback (most recent call last):
  File "/home/asus/code/RecommendedReader/socketServer.py", line 71, in process
    rowcount = cursor.rowcount
AttributeError: 'NoneType' object has no attribute 'rowcount'

2013-08-21 00:03:41,647 - mylog - ERROR - (1064, "You have an error in your SQL syntax; check the manual that corresponds to your MySQL server version for the right syntax to use near 'order by weight' at line 1")
2013-08-21 00:03:41,647 - mylog - ERROR - (1064, "You have an error in your SQL syntax; check the manual that corresponds to your MySQL server version for the right syntax to use near 'order by weight' at line 1")
2013-08-21 00:03:41,648 - mylog - ERROR - Traceback (most recent call last):
  File "/home/asus/code/RecommendedReader/socketServer.py", line 71, in process
    rowcount = cursor.rowcount
AttributeError: 'NoneType' object has no attribute 'rowcount'

2013-08-21 00:03:41,648 - mylog - ERROR - Traceback (most recent call last):
  File "/home/asus/code/RecommendedReader/socketServer.py", line 71, in process
    rowcount = cursor.rowcount
AttributeError: 'NoneType' object has no attribute 'rowcount'

2013-08-21 00:03:41,648 - mylog - ERROR - Traceback (most recent call last):
  File "/home/asus/code/RecommendedReader/socketServer.py", line 71, in process
    rowcount = cursor.rowcount
AttributeError: 'NoneType' object has no attribute 'rowcount'

2013-08-21 00:22:59,199 - mylog - ERROR - (1146, "Table 'reader.reader' doesn't exist")
2013-08-21 00:22:59,199 - mylog - ERROR - (1146, "Table 'reader.reader' doesn't exist")
2013-08-21 00:22:59,200 - mylog - ERROR - Traceback (most recent call last):
  File "/home/asus/code/RecommendedReader/socketServer.py", line 71, in process
    rowcount = cursor.rowcount
AttributeError: 'NoneType' object has no attribute 'rowcount'

2013-08-21 00:22:59,200 - mylog - ERROR - Traceback (most recent call last):
  File "/home/asus/code/RecommendedReader/socketServer.py", line 71, in process
    rowcount = cursor.rowcount
AttributeError: 'NoneType' object has no attribute 'rowcount'

2013-08-21 00:22:59,200 - mylog - ERROR - Traceback (most recent call last):
  File "/home/asus/code/RecommendedReader/socketServer.py", line 71, in process
    rowcount = cursor.rowcount
AttributeError: 'NoneType' object has no attribute 'rowcount'

2013-08-21 00:23:21,455 - mylog - ERROR - Traceback (most recent call last):
  File "/home/asus/code/RecommendedReader/socketServer.py", line 71, in process
    rowcount = cursor.rowcount
AttributeError: 'tuple' object has no attribute 'rowcount'

2013-08-21 00:23:21,455 - mylog - ERROR - Traceback (most recent call last):
  File "/home/asus/code/RecommendedReader/socketServer.py", line 71, in process
    rowcount = cursor.rowcount
AttributeError: 'tuple' object has no attribute 'rowcount'

2013-08-21 23:03:55,109 - mylog - ERROR - Traceback (most recent call last):
  File "/home/asus/code/RecommendedReader/socketServer.py", line 71, in process
    rowcount = cursor.rowcount
AttributeError: 'tuple' object has no attribute 'rowcount'

2013-08-21 23:03:55,109 - mylog - ERROR - Traceback (most recent call last):
  File "/home/asus/code/RecommendedReader/socketServer.py", line 71, in process
    rowcount = cursor.rowcount
AttributeError: 'tuple' object has no attribute 'rowcount'

2013-08-21 23:14:13,904 - mylog - ERROR - Traceback (most recent call last):
  File "/home/asus/code/RecommendedReader/socketServer.py", line 71, in process
    rowcount = len(rowcount)
UnboundLocalError: local variable 'rowcount' referenced before assignment

2013-08-21 23:14:13,904 - mylog - ERROR - Traceback (most recent call last):
  File "/home/asus/code/RecommendedReader/socketServer.py", line 71, in process
    rowcount = len(rowcount)
UnboundLocalError: local variable 'rowcount' referenced before assignment

2013-08-21 23:14:38,130 - mylog - ERROR - Traceback (most recent call last):
  File "/home/asus/code/RecommendedReader/socketServer.py", line 72, in process
    result = cursor.fetchall()
AttributeError: 'tuple' object has no attribute 'fetchall'

2013-08-21 23:14:38,130 - mylog - ERROR - Traceback (most recent call last):
  File "/home/asus/code/RecommendedReader/socketServer.py", line 72, in process
    result = cursor.fetchall()
AttributeError: 'tuple' object has no attribute 'fetchall'

2013-08-25 17:14:11,063 - mylog - ERROR - Traceback (most recent call last):
  File "/home/asus/code/RecommendedReader/server.py", line 67, in getDataToSend
    arg = __getHeader(buf)
NameError: global name '_Server__getHeader' is not defined

2013-08-25 17:14:11,064 - mylog - ERROR - Traceback (most recent call last):
  File "/home/asus/code/RecommendedReader/server.py", line 67, in getDataToSend
    arg = __getHeader(buf)
NameError: global name '_Server__getHeader' is not defined

2013-08-25 17:14:11,063 - mylog - ERROR - Traceback (most recent call last):
  File "/home/asus/code/RecommendedReader/server.py", line 67, in getDataToSend
    arg = __getHeader(buf)
NameError: global name '_Server__getHeader' is not defined

2013-08-25 17:14:11,063 - mylog - ERROR - Traceback (most recent call last):
  File "/home/asus/code/RecommendedReader/server.py", line 67, in getDataToSend
    arg = __getHeader(buf)
NameError: global name '_Server__getHeader' is not defined

2013-08-25 17:14:11,064 - mylog - ERROR - Traceback (most recent call last):
  File "/home/asus/code/RecommendedReader/server.py", line 67, in getDataToSend
    arg = __getHeader(buf)
NameError: global name '_Server__getHeader' is not defined

2013-08-25 17:14:11,064 - mylog - ERROR - Traceback (most recent call last):
  File "/home/asus/code/RecommendedReader/server.py", line 67, in getDataToSend
    arg = __getHeader(buf)
NameError: global name '_Server__getHeader' is not defined

2013-08-25 17:28:31,238 - mylog - ERROR - Traceback (most recent call last):
  File "/home/asus/code/RecommendedReader/socketServer.py", line 114, in startServer
    sock.bind(('localhost',port))
  File "/usr/lib/python2.7/socket.py", line 224, in meth
    return getattr(self._sock,name)(*args)
error: [Errno 98] Address already in use

2013-08-25 17:31:15,040 - mylog - ERROR - Traceback (most recent call last):
  File "/home/asus/code/RecommendedReader/server.py", line 61, in getDataToSend
    db = db.Database()
UnboundLocalError: local variable 'db' referenced before assignment

2013-08-25 17:31:15,040 - mylog - ERROR - Traceback (most recent call last):
  File "/home/asus/code/RecommendedReader/server.py", line 61, in getDataToSend
    db = db.Database()
UnboundLocalError: local variable 'db' referenced before assignment

2013-08-25 17:31:15,044 - mylog - ERROR - Traceback (most recent call last):
  File "/home/asus/code/RecommendedReader/server.py", line 61, in getDataToSend
    db = db.Database()
UnboundLocalError: local variable 'db' referenced before assignment

2013-08-25 17:31:15,044 - mylog - ERROR - Traceback (most recent call last):
  File "/home/asus/code/RecommendedReader/server.py", line 61, in getDataToSend
    db = db.Database()
UnboundLocalError: local variable 'db' referenced before assignment

2013-08-25 17:31:15,044 - mylog - ERROR - Traceback (most recent call last):
  File "/home/asus/code/RecommendedReader/server.py", line 61, in getDataToSend
    db = db.Database()
UnboundLocalError: local variable 'db' referenced before assignment

2013-08-25 17:31:57,831 - mylog - ERROR - Traceback (most recent call last):
  File "/home/asus/code/RecommendedReader/socketServer.py", line 114, in startServer
    sock.bind(('localhost',port))
  File "/usr/lib/python2.7/socket.py", line 224, in meth
    return getattr(self._sock,name)(*args)
error: [Errno 98] Address already in use

2013-08-25 17:32:57,348 - mylog - ERROR - Traceback (most recent call last):
  File "/home/asus/code/RecommendedReader/server.py", line 63, in getDataToSend
    arg = __getHeader(buf)
NameError: global name '_Service__getHeader' is not defined

2013-08-25 17:32:57,348 - mylog - ERROR - Traceback (most recent call last):
  File "/home/asus/code/RecommendedReader/server.py", line 63, in getDataToSend
    arg = __getHeader(buf)
NameError: global name '_Service__getHeader' is not defined

2013-08-25 17:32:57,349 - mylog - ERROR - Traceback (most recent call last):
  File "/home/asus/code/RecommendedReader/database.py", line 62, in __del__
    self.__conn.close()
ProgrammingError: closing a closed connection

2013-08-25 17:32:57,349 - mylog - ERROR - Traceback (most recent call last):
  File "/home/asus/code/RecommendedReader/database.py", line 62, in __del__
    self.__conn.close()
ProgrammingError: closing a closed connection

2013-08-25 17:32:57,349 - mylog - ERROR - Traceback (most recent call last):
  File "/home/asus/code/RecommendedReader/database.py", line 62, in __del__
    self.__conn.close()
ProgrammingError: closing a closed connection

2013-08-25 17:32:57,350 - mylog - ERROR - Traceback (most recent call last):
  File "/home/asus/code/RecommendedReader/server.py", line 63, in getDataToSend
    arg = __getHeader(buf)
NameError: global name '_Service__getHeader' is not defined

2013-08-25 17:32:57,350 - mylog - ERROR - Traceback (most recent call last):
  File "/home/asus/code/RecommendedReader/server.py", line 63, in getDataToSend
    arg = __getHeader(buf)
NameError: global name '_Service__getHeader' is not defined

2013-08-25 17:32:57,350 - mylog - ERROR - Traceback (most recent call last):
  File "/home/asus/code/RecommendedReader/server.py", line 63, in getDataToSend
    arg = __getHeader(buf)
NameError: global name '_Service__getHeader' is not defined

2013-08-25 17:32:57,350 - mylog - ERROR - Traceback (most recent call last):
  File "/home/asus/code/RecommendedReader/server.py", line 63, in getDataToSend
    arg = __getHeader(buf)
NameError: global name '_Service__getHeader' is not defined

2013-08-25 17:32:57,351 - mylog - ERROR - Traceback (most recent call last):
  File "/home/asus/code/RecommendedReader/database.py", line 62, in __del__
    self.__conn.close()
ProgrammingError: closing a closed connection

2013-08-25 17:32:57,351 - mylog - ERROR - Traceback (most recent call last):
  File "/home/asus/code/RecommendedReader/database.py", line 62, in __del__
    self.__conn.close()
ProgrammingError: closing a closed connection

2013-08-25 17:32:57,351 - mylog - ERROR - Traceback (most recent call last):
  File "/home/asus/code/RecommendedReader/database.py", line 62, in __del__
    self.__conn.close()
ProgrammingError: closing a closed connection

2013-08-25 17:32:57,351 - mylog - ERROR - Traceback (most recent call last):
  File "/home/asus/code/RecommendedReader/database.py", line 62, in __del__
    self.__conn.close()
ProgrammingError: closing a closed connection

2013-08-25 17:32:57,351 - mylog - ERROR - Traceback (most recent call last):
  File "/home/asus/code/RecommendedReader/database.py", line 62, in __del__
    self.__conn.close()
ProgrammingError: closing a closed connection

2013-08-25 17:35:01,443 - mylog - ERROR - Traceback (most recent call last):
  File "/home/asus/code/RecommendedReader/server.py", line 62, in getDataToSend
    arg = __getHeader(buf)
NameError: global name '_Service__getHeader' is not defined

2013-08-25 17:35:01,443 - mylog - ERROR - Traceback (most recent call last):
  File "/home/asus/code/RecommendedReader/server.py", line 62, in getDataToSend
    arg = __getHeader(buf)
NameError: global name '_Service__getHeader' is not defined

2013-08-25 17:35:01,443 - mylog - ERROR - Traceback (most recent call last):
  File "/home/asus/code/RecommendedReader/server.py", line 62, in getDataToSend
    arg = __getHeader(buf)
NameError: global name '_Service__getHeader' is not defined

2013-08-25 17:35:01,444 - mylog - ERROR - Traceback (most recent call last):
  File "/home/asus/code/RecommendedReader/server.py", line 62, in getDataToSend
    arg = __getHeader(buf)
NameError: global name '_Service__getHeader' is not defined

2013-08-25 17:35:01,446 - mylog - ERROR - Traceback (most recent call last):
  File "/home/asus/code/RecommendedReader/database.py", line 62, in __del__
    self.__conn.close()
ProgrammingError: closing a closed connection

2013-08-25 17:35:01,444 - mylog - ERROR - Traceback (most recent call last):
  File "/home/asus/code/RecommendedReader/server.py", line 62, in getDataToSend
    arg = __getHeader(buf)
NameError: global name '_Service__getHeader' is not defined

2013-08-25 17:35:01,446 - mylog - ERROR - Traceback (most recent call last):
  File "/home/asus/code/RecommendedReader/database.py", line 62, in __del__
    self.__conn.close()
ProgrammingError: closing a closed connection

2013-08-25 17:35:01,444 - mylog - ERROR - Traceback (most recent call last):
  File "/home/asus/code/RecommendedReader/server.py", line 62, in getDataToSend
    arg = __getHeader(buf)
NameError: global name '_Service__getHeader' is not defined

2013-08-25 17:35:01,446 - mylog - ERROR - Traceback (most recent call last):
  File "/home/asus/code/RecommendedReader/database.py", line 62, in __del__
    self.__conn.close()
ProgrammingError: closing a closed connection

2013-08-25 17:35:01,444 - mylog - ERROR - Traceback (most recent call last):
  File "/home/asus/code/RecommendedReader/server.py", line 62, in getDataToSend
    arg = __getHeader(buf)
NameError: global name '_Service__getHeader' is not defined

2013-08-25 17:35:01,446 - mylog - ERROR - Traceback (most recent call last):
  File "/home/asus/code/RecommendedReader/database.py", line 62, in __del__
    self.__conn.close()
ProgrammingError: closing a closed connection

2013-08-25 17:35:01,448 - mylog - ERROR - Traceback (most recent call last):
  File "/home/asus/code/RecommendedReader/database.py", line 62, in __del__
    self.__conn.close()
ProgrammingError: closing a closed connection

2013-08-25 17:35:01,446 - mylog - ERROR - Traceback (most recent call last):
  File "/home/asus/code/RecommendedReader/database.py", line 62, in __del__
    self.__conn.close()
ProgrammingError: closing a closed connection

2013-08-25 17:35:01,448 - mylog - ERROR - Traceback (most recent call last):
  File "/home/asus/code/RecommendedReader/database.py", line 62, in __del__
    self.__conn.close()
ProgrammingError: closing a closed connection

2013-08-25 17:35:01,448 - mylog - ERROR - Traceback (most recent call last):
  File "/home/asus/code/RecommendedReader/database.py", line 62, in __del__
    self.__conn.close()
ProgrammingError: closing a closed connection

2013-08-25 17:35:01,448 - mylog - ERROR - Traceback (most recent call last):
  File "/home/asus/code/RecommendedReader/database.py", line 62, in __del__
    self.__conn.close()
ProgrammingError: closing a closed connection

2013-08-25 17:35:01,448 - mylog - ERROR - Traceback (most recent call last):
  File "/home/asus/code/RecommendedReader/database.py", line 62, in __del__
    self.__conn.close()
ProgrammingError: closing a closed connection

2013-08-25 17:35:34,342 - mylog - ERROR - Traceback (most recent call last):
  File "/home/asus/code/RecommendedReader/socketServer.py", line 114, in startServer
    sock.bind(('localhost',port))
  File "/usr/lib/python2.7/socket.py", line 224, in meth
    return getattr(self._sock,name)(*args)
error: [Errno 98] Address already in use

2013-08-25 17:35:42,939 - mylog - ERROR - Traceback (most recent call last):
  File "/home/asus/code/RecommendedReader/socketServer.py", line 114, in startServer
    sock.bind(('localhost',port))
  File "/usr/lib/python2.7/socket.py", line 224, in meth
    return getattr(self._sock,name)(*args)
error: [Errno 98] Address already in use

2013-08-25 17:35:56,914 - mylog - ERROR - Traceback (most recent call last):
  File "/home/asus/code/RecommendedReader/socketServer.py", line 114, in startServer
    sock.bind(('localhost',port))
  File "/usr/lib/python2.7/socket.py", line 224, in meth
    return getattr(self._sock,name)(*args)
error: [Errno 98] Address already in use

2013-08-25 17:36:16,618 - mylog - ERROR - Traceback (most recent call last):
  File "/home/asus/code/RecommendedReader/server.py", line 62, in getDataToSend
    arg = self.__getHeader(buf)
TypeError: __getHeader() takes exactly 1 argument (2 given)

2013-08-25 17:36:16,618 - mylog - ERROR - Traceback (most recent call last):
  File "/home/asus/code/RecommendedReader/server.py", line 62, in getDataToSend
    arg = self.__getHeader(buf)
TypeError: __getHeader() takes exactly 1 argument (2 given)

2013-08-25 17:36:16,618 - mylog - ERROR - Traceback (most recent call last):
  File "/home/asus/code/RecommendedReader/server.py", line 62, in getDataToSend
    arg = self.__getHeader(buf)
TypeError: __getHeader() takes exactly 1 argument (2 given)

2013-08-25 17:36:16,619 - mylog - ERROR - Traceback (most recent call last):
  File "/home/asus/code/RecommendedReader/database.py", line 62, in __del__
    self.__conn.close()
ProgrammingError: closing a closed connection

2013-08-25 17:36:16,619 - mylog - ERROR - Traceback (most recent call last):
  File "/home/asus/code/RecommendedReader/database.py", line 62, in __del__
    self.__conn.close()
ProgrammingError: closing a closed connection

2013-08-25 17:36:16,619 - mylog - ERROR - Traceback (most recent call last):
  File "/home/asus/code/RecommendedReader/database.py", line 62, in __del__
    self.__conn.close()
ProgrammingError: closing a closed connection

2013-08-25 17:36:16,619 - mylog - ERROR - Traceback (most recent call last):
  File "/home/asus/code/RecommendedReader/database.py", line 62, in __del__
    self.__conn.close()
ProgrammingError: closing a closed connection

2013-08-25 17:36:16,618 - mylog - ERROR - Traceback (most recent call last):
  File "/home/asus/code/RecommendedReader/server.py", line 62, in getDataToSend
    arg = self.__getHeader(buf)
TypeError: __getHeader() takes exactly 1 argument (2 given)

2013-08-25 17:36:16,618 - mylog - ERROR - Traceback (most recent call last):
  File "/home/asus/code/RecommendedReader/server.py", line 62, in getDataToSend
    arg = self.__getHeader(buf)
TypeError: __getHeader() takes exactly 1 argument (2 given)

2013-08-25 17:36:16,618 - mylog - ERROR - Traceback (most recent call last):
  File "/home/asus/code/RecommendedReader/server.py", line 62, in getDataToSend
    arg = self.__getHeader(buf)
TypeError: __getHeader() takes exactly 1 argument (2 given)

2013-08-25 17:36:16,618 - mylog - ERROR - Traceback (most recent call last):
  File "/home/asus/code/RecommendedReader/server.py", line 62, in getDataToSend
    arg = self.__getHeader(buf)
TypeError: __getHeader() takes exactly 1 argument (2 given)

2013-08-25 17:36:16,621 - mylog - ERROR - Traceback (most recent call last):
  File "/home/asus/code/RecommendedReader/database.py", line 62, in __del__
    self.__conn.close()
ProgrammingError: closing a closed connection

2013-08-25 17:36:16,621 - mylog - ERROR - Traceback (most recent call last):
  File "/home/asus/code/RecommendedReader/database.py", line 62, in __del__
    self.__conn.close()
ProgrammingError: closing a closed connection

2013-08-25 17:36:16,621 - mylog - ERROR - Traceback (most recent call last):
  File "/home/asus/code/RecommendedReader/database.py", line 62, in __del__
    self.__conn.close()
ProgrammingError: closing a closed connection

2013-08-25 17:36:16,621 - mylog - ERROR - Traceback (most recent call last):
  File "/home/asus/code/RecommendedReader/database.py", line 62, in __del__
    self.__conn.close()
ProgrammingError: closing a closed connection

2013-08-25 17:36:16,621 - mylog - ERROR - Traceback (most recent call last):
  File "/home/asus/code/RecommendedReader/database.py", line 62, in __del__
    self.__conn.close()
ProgrammingError: closing a closed connection

2013-08-25 17:37:37,414 - mylog - ERROR - Traceback (most recent call last):
  File "/home/asus/code/RecommendedReader/server.py", line 63, in getDataToSend
    actionType = arg[0]
TypeError: 'NoneType' object has no attribute '__getitem__'

2013-08-25 17:37:37,415 - mylog - ERROR - Traceback (most recent call last):
  File "/home/asus/code/RecommendedReader/server.py", line 63, in getDataToSend
    actionType = arg[0]
TypeError: 'NoneType' object has no attribute '__getitem__'

2013-08-25 17:37:37,414 - mylog - ERROR - Traceback (most recent call last):
  File "/home/asus/code/RecommendedReader/server.py", line 63, in getDataToSend
    actionType = arg[0]
TypeError: 'NoneType' object has no attribute '__getitem__'

2013-08-25 17:37:37,414 - mylog - ERROR - Traceback (most recent call last):
  File "/home/asus/code/RecommendedReader/server.py", line 63, in getDataToSend
    actionType = arg[0]
TypeError: 'NoneType' object has no attribute '__getitem__'

2013-08-25 17:37:37,415 - mylog - ERROR - Traceback (most recent call last):
  File "/home/asus/code/RecommendedReader/server.py", line 63, in getDataToSend
    actionType = arg[0]
TypeError: 'NoneType' object has no attribute '__getitem__'

2013-08-25 17:37:37,415 - mylog - ERROR - Traceback (most recent call last):
  File "/home/asus/code/RecommendedReader/server.py", line 63, in getDataToSend
    actionType = arg[0]
TypeError: 'NoneType' object has no attribute '__getitem__'

2013-08-25 17:37:37,415 - mylog - ERROR - Traceback (most recent call last):
  File "/home/asus/code/RecommendedReader/server.py", line 63, in getDataToSend
    actionType = arg[0]
TypeError: 'NoneType' object has no attribute '__getitem__'

2013-08-25 17:37:37,417 - mylog - ERROR - Traceback (most recent call last):
  File "/home/asus/code/RecommendedReader/database.py", line 62, in __del__
    self.__conn.close()
ProgrammingError: closing a closed connection

2013-08-25 17:37:37,417 - mylog - ERROR - Traceback (most recent call last):
  File "/home/asus/code/RecommendedReader/database.py", line 62, in __del__
    self.__conn.close()
ProgrammingError: closing a closed connection

2013-08-25 17:37:37,417 - mylog - ERROR - Traceback (most recent call last):
  File "/home/asus/code/RecommendedReader/database.py", line 62, in __del__
    self.__conn.close()
ProgrammingError: closing a closed connection

2013-08-25 17:37:37,417 - mylog - ERROR - Traceback (most recent call last):
  File "/home/asus/code/RecommendedReader/database.py", line 62, in __del__
    self.__conn.close()
ProgrammingError: closing a closed connection

2013-08-25 17:37:37,417 - mylog - ERROR - Traceback (most recent call last):
  File "/home/asus/code/RecommendedReader/database.py", line 62, in __del__
    self.__conn.close()
ProgrammingError: closing a closed connection

2013-08-25 17:37:37,417 - mylog - ERROR - Traceback (most recent call last):
  File "/home/asus/code/RecommendedReader/database.py", line 62, in __del__
    self.__conn.close()
ProgrammingError: closing a closed connection

2013-08-25 17:37:37,417 - mylog - ERROR - Traceback (most recent call last):
  File "/home/asus/code/RecommendedReader/database.py", line 62, in __del__
    self.__conn.close()
ProgrammingError: closing a closed connection

2013-08-25 17:37:37,417 - mylog - ERROR - Traceback (most recent call last):
  File "/home/asus/code/RecommendedReader/database.py", line 62, in __del__
    self.__conn.close()
ProgrammingError: closing a closed connection

2013-08-25 17:37:37,417 - mylog - ERROR - Traceback (most recent call last):
  File "/home/asus/code/RecommendedReader/database.py", line 62, in __del__
    self.__conn.close()
ProgrammingError: closing a closed connection

2013-08-25 17:37:37,417 - mylog - ERROR - Traceback (most recent call last):
  File "/home/asus/code/RecommendedReader/database.py", line 62, in __del__
    self.__conn.close()
ProgrammingError: closing a closed connection

2013-08-27 21:27:38,451 - mylog - ERROR - Traceback (most recent call last):
  File "/home/asus/code/RecommendedReader/server.py", line 66, in getDataToSend
    actionType = args[0]
TypeError: 'NoneType' object has no attribute '__getitem__'

2013-08-27 21:27:38,451 - mylog - ERROR - Traceback (most recent call last):
  File "/home/asus/code/RecommendedReader/server.py", line 66, in getDataToSend
    actionType = args[0]
TypeError: 'NoneType' object has no attribute '__getitem__'

2013-08-27 21:27:38,451 - mylog - ERROR - Traceback (most recent call last):
  File "/home/asus/code/RecommendedReader/server.py", line 66, in getDataToSend
    actionType = args[0]
TypeError: 'NoneType' object has no attribute '__getitem__'

2013-08-27 21:27:38,451 - mylog - ERROR - Traceback (most recent call last):
  File "/home/asus/code/RecommendedReader/server.py", line 66, in getDataToSend
    actionType = args[0]
TypeError: 'NoneType' object has no attribute '__getitem__'

2013-08-27 21:27:38,451 - mylog - ERROR - Traceback (most recent call last):
  File "/home/asus/code/RecommendedReader/server.py", line 66, in getDataToSend
    actionType = args[0]
TypeError: 'NoneType' object has no attribute '__getitem__'

2013-08-27 21:27:38,451 - mylog - ERROR - Traceback (most recent call last):
  File "/home/asus/code/RecommendedReader/server.py", line 66, in getDataToSend
    actionType = args[0]
TypeError: 'NoneType' object has no attribute '__getitem__'

2013-08-27 21:27:38,451 - mylog - ERROR - Traceback (most recent call last):
  File "/home/asus/code/RecommendedReader/server.py", line 66, in getDataToSend
    actionType = args[0]
TypeError: 'NoneType' object has no attribute '__getitem__'

2013-08-27 21:27:38,499 - mylog - ERROR - Traceback (most recent call last):
  File "/home/asus/code/RecommendedReader/database.py", line 62, in __del__
    self.__conn.close()
ProgrammingError: closing a closed connection

2013-08-27 21:27:38,499 - mylog - ERROR - Traceback (most recent call last):
  File "/home/asus/code/RecommendedReader/database.py", line 62, in __del__
    self.__conn.close()
ProgrammingError: closing a closed connection

2013-08-27 21:27:38,499 - mylog - ERROR - Traceback (most recent call last):
  File "/home/asus/code/RecommendedReader/database.py", line 62, in __del__
    self.__conn.close()
ProgrammingError: closing a closed connection

2013-08-27 21:27:38,499 - mylog - ERROR - Traceback (most recent call last):
  File "/home/asus/code/RecommendedReader/database.py", line 62, in __del__
    self.__conn.close()
ProgrammingError: closing a closed connection

2013-08-27 21:27:38,499 - mylog - ERROR - Traceback (most recent call last):
  File "/home/asus/code/RecommendedReader/database.py", line 62, in __del__
    self.__conn.close()
ProgrammingError: closing a closed connection

2013-08-27 21:27:38,501 - mylog - ERROR - Traceback (most recent call last):
  File "/home/asus/code/RecommendedReader/database.py", line 62, in __del__
    self.__conn.close()
ProgrammingError: closing a closed connection

2013-08-27 21:27:38,501 - mylog - ERROR - Traceback (most recent call last):
  File "/home/asus/code/RecommendedReader/database.py", line 62, in __del__
    self.__conn.close()
ProgrammingError: closing a closed connection

2013-08-27 21:27:38,501 - mylog - ERROR - Traceback (most recent call last):
  File "/home/asus/code/RecommendedReader/database.py", line 62, in __del__
    self.__conn.close()
ProgrammingError: closing a closed connection

2013-08-27 21:27:38,501 - mylog - ERROR - Traceback (most recent call last):
  File "/home/asus/code/RecommendedReader/database.py", line 62, in __del__
    self.__conn.close()
ProgrammingError: closing a closed connection

2013-08-27 21:27:38,501 - mylog - ERROR - Traceback (most recent call last):
  File "/home/asus/code/RecommendedReader/database.py", line 62, in __del__
    self.__conn.close()
ProgrammingError: closing a closed connection

2013-08-27 21:43:33,389 - mylog - ERROR - Traceback (most recent call last):
  File "/home/asus/code/RecommendedReader/server.py", line 66, in getDataToSend
    actionType = args[0]
TypeError: 'NoneType' object has no attribute '__getitem__'

2013-08-27 21:43:33,389 - mylog - ERROR - Traceback (most recent call last):
  File "/home/asus/code/RecommendedReader/server.py", line 66, in getDataToSend
    actionType = args[0]
TypeError: 'NoneType' object has no attribute '__getitem__'

2013-08-27 21:43:33,389 - mylog - ERROR - Traceback (most recent call last):
  File "/home/asus/code/RecommendedReader/server.py", line 66, in getDataToSend
    actionType = args[0]
TypeError: 'NoneType' object has no attribute '__getitem__'

2013-08-27 21:43:33,389 - mylog - ERROR - Traceback (most recent call last):
  File "/home/asus/code/RecommendedReader/server.py", line 66, in getDataToSend
    actionType = args[0]
TypeError: 'NoneType' object has no attribute '__getitem__'

2013-08-27 21:43:33,389 - mylog - ERROR - Traceback (most recent call last):
  File "/home/asus/code/RecommendedReader/server.py", line 66, in getDataToSend
    actionType = args[0]
TypeError: 'NoneType' object has no attribute '__getitem__'

2013-08-27 21:43:33,389 - mylog - ERROR - Traceback (most recent call last):
  File "/home/asus/code/RecommendedReader/server.py", line 66, in getDataToSend
    actionType = args[0]
TypeError: 'NoneType' object has no attribute '__getitem__'

2013-08-27 21:43:33,391 - mylog - ERROR - Traceback (most recent call last):
  File "/home/asus/code/RecommendedReader/database.py", line 62, in __del__
    self.__conn.close()
ProgrammingError: closing a closed connection

2013-08-27 21:43:33,391 - mylog - ERROR - Traceback (most recent call last):
  File "/home/asus/code/RecommendedReader/database.py", line 62, in __del__
    self.__conn.close()
ProgrammingError: closing a closed connection

2013-08-27 21:43:33,391 - mylog - ERROR - Traceback (most recent call last):
  File "/home/asus/code/RecommendedReader/database.py", line 62, in __del__
    self.__conn.close()
ProgrammingError: closing a closed connection

2013-08-27 21:43:33,391 - mylog - ERROR - Traceback (most recent call last):
  File "/home/asus/code/RecommendedReader/database.py", line 62, in __del__
    self.__conn.close()
ProgrammingError: closing a closed connection

2013-08-27 21:43:33,393 - mylog - ERROR - Traceback (most recent call last):
  File "/home/asus/code/RecommendedReader/database.py", line 62, in __del__
    self.__conn.close()
ProgrammingError: closing a closed connection

2013-08-27 21:43:33,393 - mylog - ERROR - Traceback (most recent call last):
  File "/home/asus/code/RecommendedReader/database.py", line 62, in __del__
    self.__conn.close()
ProgrammingError: closing a closed connection

2013-08-27 21:43:33,393 - mylog - ERROR - Traceback (most recent call last):
  File "/home/asus/code/RecommendedReader/database.py", line 62, in __del__
    self.__conn.close()
ProgrammingError: closing a closed connection

2013-08-27 21:43:33,393 - mylog - ERROR - Traceback (most recent call last):
  File "/home/asus/code/RecommendedReader/database.py", line 62, in __del__
    self.__conn.close()
ProgrammingError: closing a closed connection

2013-08-27 21:43:33,393 - mylog - ERROR - Traceback (most recent call last):
  File "/home/asus/code/RecommendedReader/database.py", line 62, in __del__
    self.__conn.close()
ProgrammingError: closing a closed connection

2013-08-27 21:52:08,676 - mylog - ERROR - Traceback (most recent call last):
  File "/home/asus/code/RecommendedReader/server.py", line 69, in getDataToSend
    actionType = args[0]
TypeError: 'NoneType' object has no attribute '__getitem__'

2013-08-27 21:52:08,677 - mylog - ERROR - Traceback (most recent call last):
  File "/home/asus/code/RecommendedReader/server.py", line 69, in getDataToSend
    actionType = args[0]
TypeError: 'NoneType' object has no attribute '__getitem__'

2013-08-27 21:52:08,676 - mylog - ERROR - Traceback (most recent call last):
  File "/home/asus/code/RecommendedReader/server.py", line 69, in getDataToSend
    actionType = args[0]
TypeError: 'NoneType' object has no attribute '__getitem__'

2013-08-27 21:52:08,677 - mylog - ERROR - Traceback (most recent call last):
  File "/home/asus/code/RecommendedReader/server.py", line 69, in getDataToSend
    actionType = args[0]
TypeError: 'NoneType' object has no attribute '__getitem__'

2013-08-27 21:52:08,676 - mylog - ERROR - Traceback (most recent call last):
  File "/home/asus/code/RecommendedReader/server.py", line 69, in getDataToSend
    actionType = args[0]
TypeError: 'NoneType' object has no attribute '__getitem__'

2013-08-27 21:52:08,677 - mylog - ERROR - Traceback (most recent call last):
  File "/home/asus/code/RecommendedReader/server.py", line 69, in getDataToSend
    actionType = args[0]
TypeError: 'NoneType' object has no attribute '__getitem__'

2013-08-27 21:52:08,679 - mylog - ERROR - Traceback (most recent call last):
  File "/home/asus/code/RecommendedReader/database.py", line 62, in __del__
    self.__conn.close()
ProgrammingError: closing a closed connection

2013-08-27 21:52:08,677 - mylog - ERROR - Traceback (most recent call last):
  File "/home/asus/code/RecommendedReader/server.py", line 69, in getDataToSend
    actionType = args[0]
TypeError: 'NoneType' object has no attribute '__getitem__'

2013-08-27 21:52:08,679 - mylog - ERROR - Traceback (most recent call last):
  File "/home/asus/code/RecommendedReader/database.py", line 62, in __del__
    self.__conn.close()
ProgrammingError: closing a closed connection

2013-08-27 21:52:08,680 - mylog - ERROR - Traceback (most recent call last):
  File "/home/asus/code/RecommendedReader/database.py", line 62, in __del__
    self.__conn.close()
ProgrammingError: closing a closed connection

2013-08-27 21:52:08,679 - mylog - ERROR - Traceback (most recent call last):
  File "/home/asus/code/RecommendedReader/database.py", line 62, in __del__
    self.__conn.close()
ProgrammingError: closing a closed connection

2013-08-27 21:52:08,680 - mylog - ERROR - Traceback (most recent call last):
  File "/home/asus/code/RecommendedReader/database.py", line 62, in __del__
    self.__conn.close()
ProgrammingError: closing a closed connection

2013-08-27 21:52:08,679 - mylog - ERROR - Traceback (most recent call last):
  File "/home/asus/code/RecommendedReader/database.py", line 62, in __del__
    self.__conn.close()
ProgrammingError: closing a closed connection

2013-08-27 21:52:08,680 - mylog - ERROR - Traceback (most recent call last):
  File "/home/asus/code/RecommendedReader/database.py", line 62, in __del__
    self.__conn.close()
ProgrammingError: closing a closed connection

2013-08-27 21:52:08,679 - mylog - ERROR - Traceback (most recent call last):
  File "/home/asus/code/RecommendedReader/database.py", line 62, in __del__
    self.__conn.close()
ProgrammingError: closing a closed connection

2013-08-27 21:52:08,680 - mylog - ERROR - Traceback (most recent call last):
  File "/home/asus/code/RecommendedReader/database.py", line 62, in __del__
    self.__conn.close()
ProgrammingError: closing a closed connection

2013-08-27 21:52:08,680 - mylog - ERROR - Traceback (most recent call last):
  File "/home/asus/code/RecommendedReader/database.py", line 62, in __del__
    self.__conn.close()
ProgrammingError: closing a closed connection

2013-08-27 21:53:40,625 - mylog - ERROR - Traceback (most recent call last):
  File "/home/asus/code/RecommendedReader/server.py", line 69, in getDataToSend
    actionType = args[0]
TypeError: 'NoneType' object has no attribute '__getitem__'

2013-08-27 21:53:40,625 - mylog - ERROR - Traceback (most recent call last):
  File "/home/asus/code/RecommendedReader/server.py", line 69, in getDataToSend
    actionType = args[0]
TypeError: 'NoneType' object has no attribute '__getitem__'

2013-08-27 21:53:40,626 - mylog - ERROR - Traceback (most recent call last):
  File "/home/asus/code/RecommendedReader/server.py", line 69, in getDataToSend
    actionType = args[0]
TypeError: 'NoneType' object has no attribute '__getitem__'

2013-08-27 21:53:40,626 - mylog - ERROR - Traceback (most recent call last):
  File "/home/asus/code/RecommendedReader/server.py", line 69, in getDataToSend
    actionType = args[0]
TypeError: 'NoneType' object has no attribute '__getitem__'

2013-08-27 21:53:40,625 - mylog - ERROR - Traceback (most recent call last):
  File "/home/asus/code/RecommendedReader/server.py", line 69, in getDataToSend
    actionType = args[0]
TypeError: 'NoneType' object has no attribute '__getitem__'

2013-08-27 21:53:40,626 - mylog - ERROR - Traceback (most recent call last):
  File "/home/asus/code/RecommendedReader/server.py", line 69, in getDataToSend
    actionType = args[0]
TypeError: 'NoneType' object has no attribute '__getitem__'

2013-08-27 21:53:40,629 - mylog - ERROR - Traceback (most recent call last):
  File "/home/asus/code/RecommendedReader/database.py", line 62, in __del__
    self.__conn.close()
ProgrammingError: closing a closed connection

2013-08-27 21:53:40,629 - mylog - ERROR - Traceback (most recent call last):
  File "/home/asus/code/RecommendedReader/database.py", line 62, in __del__
    self.__conn.close()
ProgrammingError: closing a closed connection

2013-08-27 21:53:40,629 - mylog - ERROR - Traceback (most recent call last):
  File "/home/asus/code/RecommendedReader/database.py", line 62, in __del__
    self.__conn.close()
ProgrammingError: closing a closed connection

2013-08-27 21:53:40,629 - mylog - ERROR - Traceback (most recent call last):
  File "/home/asus/code/RecommendedReader/database.py", line 62, in __del__
    self.__conn.close()
ProgrammingError: closing a closed connection

2013-08-27 21:53:40,629 - mylog - ERROR - Traceback (most recent call last):
  File "/home/asus/code/RecommendedReader/database.py", line 62, in __del__
    self.__conn.close()
ProgrammingError: closing a closed connection

2013-08-27 21:53:40,629 - mylog - ERROR - Traceback (most recent call last):
  File "/home/asus/code/RecommendedReader/database.py", line 62, in __del__
    self.__conn.close()
ProgrammingError: closing a closed connection

2013-08-27 21:53:40,629 - mylog - ERROR - Traceback (most recent call last):
  File "/home/asus/code/RecommendedReader/database.py", line 62, in __del__
    self.__conn.close()
ProgrammingError: closing a closed connection

2013-08-27 21:53:40,629 - mylog - ERROR - Traceback (most recent call last):
  File "/home/asus/code/RecommendedReader/database.py", line 62, in __del__
    self.__conn.close()
ProgrammingError: closing a closed connection

2013-08-27 21:53:40,629 - mylog - ERROR - Traceback (most recent call last):
  File "/home/asus/code/RecommendedReader/database.py", line 62, in __del__
    self.__conn.close()
ProgrammingError: closing a closed connection

2013-08-27 21:53:40,629 - mylog - ERROR - Traceback (most recent call last):
  File "/home/asus/code/RecommendedReader/database.py", line 62, in __del__
    self.__conn.close()
ProgrammingError: closing a closed connection

2013-08-27 21:54:47,387 - mylog - ERROR - Traceback (most recent call last):
  File "/home/asus/code/RecommendedReader/server.py", line 69, in getDataToSend
    actionType = args[0]
TypeError: 'NoneType' object has no attribute '__getitem__'

2013-08-27 21:54:47,387 - mylog - ERROR - Traceback (most recent call last):
  File "/home/asus/code/RecommendedReader/server.py", line 69, in getDataToSend
    actionType = args[0]
TypeError: 'NoneType' object has no attribute '__getitem__'

2013-08-27 21:54:47,388 - mylog - ERROR - Traceback (most recent call last):
  File "/home/asus/code/RecommendedReader/database.py", line 62, in __del__
    self.__conn.close()
ProgrammingError: closing a closed connection

2013-08-27 21:54:47,388 - mylog - ERROR - Traceback (most recent call last):
  File "/home/asus/code/RecommendedReader/database.py", line 62, in __del__
    self.__conn.close()
ProgrammingError: closing a closed connection

2013-08-27 21:54:47,388 - mylog - ERROR - Traceback (most recent call last):
  File "/home/asus/code/RecommendedReader/database.py", line 62, in __del__
    self.__conn.close()
ProgrammingError: closing a closed connection

2013-08-27 21:54:47,389 - mylog - ERROR - Traceback (most recent call last):
  File "/home/asus/code/RecommendedReader/server.py", line 69, in getDataToSend
    actionType = args[0]
TypeError: 'NoneType' object has no attribute '__getitem__'

2013-08-27 21:54:47,389 - mylog - ERROR - Traceback (most recent call last):
  File "/home/asus/code/RecommendedReader/server.py", line 69, in getDataToSend
    actionType = args[0]
TypeError: 'NoneType' object has no attribute '__getitem__'

2013-08-27 21:54:47,389 - mylog - ERROR - Traceback (most recent call last):
  File "/home/asus/code/RecommendedReader/server.py", line 69, in getDataToSend
    actionType = args[0]
TypeError: 'NoneType' object has no attribute '__getitem__'

2013-08-27 21:54:47,389 - mylog - ERROR - Traceback (most recent call last):
  File "/home/asus/code/RecommendedReader/server.py", line 69, in getDataToSend
    actionType = args[0]
TypeError: 'NoneType' object has no attribute '__getitem__'

2013-08-27 21:54:47,390 - mylog - ERROR - Traceback (most recent call last):
  File "/home/asus/code/RecommendedReader/database.py", line 62, in __del__
    self.__conn.close()
ProgrammingError: closing a closed connection

2013-08-27 21:54:47,390 - mylog - ERROR - Traceback (most recent call last):
  File "/home/asus/code/RecommendedReader/database.py", line 62, in __del__
    self.__conn.close()
ProgrammingError: closing a closed connection

2013-08-27 21:54:47,390 - mylog - ERROR - Traceback (most recent call last):
  File "/home/asus/code/RecommendedReader/database.py", line 62, in __del__
    self.__conn.close()
ProgrammingError: closing a closed connection

2013-08-27 21:54:47,390 - mylog - ERROR - Traceback (most recent call last):
  File "/home/asus/code/RecommendedReader/database.py", line 62, in __del__
    self.__conn.close()
ProgrammingError: closing a closed connection

2013-08-27 21:54:47,390 - mylog - ERROR - Traceback (most recent call last):
  File "/home/asus/code/RecommendedReader/database.py", line 62, in __del__
    self.__conn.close()
ProgrammingError: closing a closed connection

2013-08-27 22:06:50,911 - mylog - ERROR - Traceback (most recent call last):
  File "/home/asus/code/RecommendedReader/server.py", line 69, in getDataToSend
    actionType = args[0]
TypeError: 'NoneType' object has no attribute '__getitem__'

2013-08-27 22:06:50,911 - mylog - ERROR - Traceback (most recent call last):
  File "/home/asus/code/RecommendedReader/server.py", line 69, in getDataToSend
    actionType = args[0]
TypeError: 'NoneType' object has no attribute '__getitem__'

2013-08-27 22:06:50,912 - mylog - ERROR - Traceback (most recent call last):
  File "/home/asus/code/RecommendedReader/database.py", line 62, in __del__
    self.__conn.close()
ProgrammingError: closing a closed connection

2013-08-27 22:06:50,912 - mylog - ERROR - Traceback (most recent call last):
  File "/home/asus/code/RecommendedReader/database.py", line 62, in __del__
    self.__conn.close()
ProgrammingError: closing a closed connection

2013-08-27 22:06:50,912 - mylog - ERROR - Traceback (most recent call last):
  File "/home/asus/code/RecommendedReader/database.py", line 62, in __del__
    self.__conn.close()
ProgrammingError: closing a closed connection

2013-08-27 22:06:50,914 - mylog - ERROR - Traceback (most recent call last):
  File "/home/asus/code/RecommendedReader/server.py", line 69, in getDataToSend
    actionType = args[0]
TypeError: 'NoneType' object has no attribute '__getitem__'

2013-08-27 22:06:50,914 - mylog - ERROR - Traceback (most recent call last):
  File "/home/asus/code/RecommendedReader/server.py", line 69, in getDataToSend
    actionType = args[0]
TypeError: 'NoneType' object has no attribute '__getitem__'

2013-08-27 22:06:50,914 - mylog - ERROR - Traceback (most recent call last):
  File "/home/asus/code/RecommendedReader/server.py", line 69, in getDataToSend
    actionType = args[0]
TypeError: 'NoneType' object has no attribute '__getitem__'

2013-08-27 22:06:50,914 - mylog - ERROR - Traceback (most recent call last):
  File "/home/asus/code/RecommendedReader/server.py", line 69, in getDataToSend
    actionType = args[0]
TypeError: 'NoneType' object has no attribute '__getitem__'

2013-08-27 22:06:50,914 - mylog - ERROR - Traceback (most recent call last):
  File "/home/asus/code/RecommendedReader/database.py", line 62, in __del__
    self.__conn.close()
ProgrammingError: closing a closed connection

2013-08-27 22:06:50,914 - mylog - ERROR - Traceback (most recent call last):
  File "/home/asus/code/RecommendedReader/database.py", line 62, in __del__
    self.__conn.close()
ProgrammingError: closing a closed connection

2013-08-27 22:06:50,914 - mylog - ERROR - Traceback (most recent call last):
  File "/home/asus/code/RecommendedReader/database.py", line 62, in __del__
    self.__conn.close()
ProgrammingError: closing a closed connection

2013-08-27 22:06:50,914 - mylog - ERROR - Traceback (most recent call last):
  File "/home/asus/code/RecommendedReader/database.py", line 62, in __del__
    self.__conn.close()
ProgrammingError: closing a closed connection

2013-08-27 22:06:50,914 - mylog - ERROR - Traceback (most recent call last):
  File "/home/asus/code/RecommendedReader/database.py", line 62, in __del__
    self.__conn.close()
ProgrammingError: closing a closed connection

2013-08-27 22:08:05,639 - mylog - ERROR - Traceback (most recent call last):
  File "/home/asus/code/RecommendedReader/server.py", line 69, in getDataToSend
    actionType = args[0]
TypeError: 'NoneType' object has no attribute '__getitem__'

2013-08-27 22:08:05,639 - mylog - ERROR - Traceback (most recent call last):
  File "/home/asus/code/RecommendedReader/server.py", line 69, in getDataToSend
    actionType = args[0]
TypeError: 'NoneType' object has no attribute '__getitem__'

2013-08-27 22:08:05,640 - mylog - ERROR - Traceback (most recent call last):
  File "/home/asus/code/RecommendedReader/server.py", line 69, in getDataToSend
    actionType = args[0]
TypeError: 'NoneType' object has no attribute '__getitem__'

2013-08-27 22:08:05,641 - mylog - ERROR - Traceback (most recent call last):
  File "/home/asus/code/RecommendedReader/database.py", line 62, in __del__
    self.__conn.close()
ProgrammingError: closing a closed connection

2013-08-27 22:08:05,640 - mylog - ERROR - Traceback (most recent call last):
  File "/home/asus/code/RecommendedReader/server.py", line 69, in getDataToSend
    actionType = args[0]
TypeError: 'NoneType' object has no attribute '__getitem__'

2013-08-27 22:08:05,641 - mylog - ERROR - Traceback (most recent call last):
  File "/home/asus/code/RecommendedReader/database.py", line 62, in __del__
    self.__conn.close()
ProgrammingError: closing a closed connection

2013-08-27 22:08:05,640 - mylog - ERROR - Traceback (most recent call last):
  File "/home/asus/code/RecommendedReader/server.py", line 69, in getDataToSend
    actionType = args[0]
TypeError: 'NoneType' object has no attribute '__getitem__'

2013-08-27 22:08:05,641 - mylog - ERROR - Traceback (most recent call last):
  File "/home/asus/code/RecommendedReader/database.py", line 62, in __del__
    self.__conn.close()
ProgrammingError: closing a closed connection

2013-08-27 22:08:05,640 - mylog - ERROR - Traceback (most recent call last):
  File "/home/asus/code/RecommendedReader/server.py", line 69, in getDataToSend
    actionType = args[0]
TypeError: 'NoneType' object has no attribute '__getitem__'

2013-08-27 22:08:05,641 - mylog - ERROR - Traceback (most recent call last):
  File "/home/asus/code/RecommendedReader/database.py", line 62, in __del__
    self.__conn.close()
ProgrammingError: closing a closed connection

2013-08-27 22:08:05,643 - mylog - ERROR - Traceback (most recent call last):
  File "/home/asus/code/RecommendedReader/database.py", line 62, in __del__
    self.__conn.close()
ProgrammingError: closing a closed connection

2013-08-27 22:08:05,641 - mylog - ERROR - Traceback (most recent call last):
  File "/home/asus/code/RecommendedReader/database.py", line 62, in __del__
    self.__conn.close()
ProgrammingError: closing a closed connection

2013-08-27 22:08:05,643 - mylog - ERROR - Traceback (most recent call last):
  File "/home/asus/code/RecommendedReader/database.py", line 62, in __del__
    self.__conn.close()
ProgrammingError: closing a closed connection

2013-08-27 22:08:05,643 - mylog - ERROR - Traceback (most recent call last):
  File "/home/asus/code/RecommendedReader/database.py", line 62, in __del__
    self.__conn.close()
ProgrammingError: closing a closed connection

2013-08-27 22:08:05,643 - mylog - ERROR - Traceback (most recent call last):
  File "/home/asus/code/RecommendedReader/database.py", line 62, in __del__
    self.__conn.close()
ProgrammingError: closing a closed connection

2013-08-27 22:08:05,643 - mylog - ERROR - Traceback (most recent call last):
  File "/home/asus/code/RecommendedReader/database.py", line 62, in __del__
    self.__conn.close()
ProgrammingError: closing a closed connection

2013-08-27 22:10:38,215 - mylog - ERROR - Traceback (most recent call last):
  File "/home/asus/code/RecommendedReader/server.py", line 67, in getDataToSend
    print "dir:" + dir(self)
TypeError: cannot concatenate 'str' and 'list' objects

2013-08-27 22:10:38,215 - mylog - ERROR - Traceback (most recent call last):
  File "/home/asus/code/RecommendedReader/server.py", line 67, in getDataToSend
    print "dir:" + dir(self)
TypeError: cannot concatenate 'str' and 'list' objects

2013-08-27 22:10:38,216 - mylog - ERROR - Traceback (most recent call last):
  File "/home/asus/code/RecommendedReader/database.py", line 62, in __del__
    self.__conn.close()
ProgrammingError: closing a closed connection

2013-08-27 22:10:38,216 - mylog - ERROR - Traceback (most recent call last):
  File "/home/asus/code/RecommendedReader/database.py", line 62, in __del__
    self.__conn.close()
ProgrammingError: closing a closed connection

2013-08-27 22:10:38,216 - mylog - ERROR - Traceback (most recent call last):
  File "/home/asus/code/RecommendedReader/database.py", line 62, in __del__
    self.__conn.close()
ProgrammingError: closing a closed connection

2013-08-27 22:10:38,218 - mylog - ERROR - Traceback (most recent call last):
  File "/home/asus/code/RecommendedReader/server.py", line 67, in getDataToSend
    print "dir:" + dir(self)
TypeError: cannot concatenate 'str' and 'list' objects

2013-08-27 22:10:38,218 - mylog - ERROR - Traceback (most recent call last):
  File "/home/asus/code/RecommendedReader/server.py", line 67, in getDataToSend
    print "dir:" + dir(self)
TypeError: cannot concatenate 'str' and 'list' objects

2013-08-27 22:10:38,218 - mylog - ERROR - Traceback (most recent call last):
  File "/home/asus/code/RecommendedReader/server.py", line 67, in getDataToSend
    print "dir:" + dir(self)
TypeError: cannot concatenate 'str' and 'list' objects

2013-08-27 22:10:38,218 - mylog - ERROR - Traceback (most recent call last):
  File "/home/asus/code/RecommendedReader/server.py", line 67, in getDataToSend
    print "dir:" + dir(self)
TypeError: cannot concatenate 'str' and 'list' objects

2013-08-27 22:10:38,219 - mylog - ERROR - Traceback (most recent call last):
  File "/home/asus/code/RecommendedReader/database.py", line 62, in __del__
    self.__conn.close()
ProgrammingError: closing a closed connection

2013-08-27 22:10:38,219 - mylog - ERROR - Traceback (most recent call last):
  File "/home/asus/code/RecommendedReader/database.py", line 62, in __del__
    self.__conn.close()
ProgrammingError: closing a closed connection

2013-08-27 22:10:38,219 - mylog - ERROR - Traceback (most recent call last):
  File "/home/asus/code/RecommendedReader/database.py", line 62, in __del__
    self.__conn.close()
ProgrammingError: closing a closed connection

2013-08-27 22:10:38,219 - mylog - ERROR - Traceback (most recent call last):
  File "/home/asus/code/RecommendedReader/database.py", line 62, in __del__
    self.__conn.close()
ProgrammingError: closing a closed connection

2013-08-27 22:10:38,219 - mylog - ERROR - Traceback (most recent call last):
  File "/home/asus/code/RecommendedReader/database.py", line 62, in __del__
    self.__conn.close()
ProgrammingError: closing a closed connection

2013-08-27 22:11:07,991 - mylog - ERROR - Traceback (most recent call last):
  File "/home/asus/code/RecommendedReader/socketServer.py", line 118, in startServer
    sock.bind(('localhost',port))
  File "/usr/lib/python2.7/socket.py", line 224, in meth
    return getattr(self._sock,name)(*args)
error: [Errno 98] Address already in use

2013-08-27 22:11:29,449 - mylog - ERROR - Traceback (most recent call last):
  File "/home/asus/code/RecommendedReader/socketServer.py", line 118, in startServer
    sock.bind(('localhost',port))
  File "/usr/lib/python2.7/socket.py", line 224, in meth
    return getattr(self._sock,name)(*args)
error: [Errno 98] Address already in use

2013-08-27 22:12:12,233 - mylog - ERROR - Traceback (most recent call last):
  File "/home/asus/code/RecommendedReader/server.py", line 71, in getDataToSend
    actionType = args[0]
TypeError: 'NoneType' object has no attribute '__getitem__'

2013-08-27 22:12:12,233 - mylog - ERROR - Traceback (most recent call last):
  File "/home/asus/code/RecommendedReader/server.py", line 71, in getDataToSend
    actionType = args[0]
TypeError: 'NoneType' object has no attribute '__getitem__'

2013-08-27 22:12:12,234 - mylog - ERROR - Traceback (most recent call last):
  File "/home/asus/code/RecommendedReader/database.py", line 62, in __del__
    self.__conn.close()
ProgrammingError: closing a closed connection

2013-08-27 22:12:12,234 - mylog - ERROR - Traceback (most recent call last):
  File "/home/asus/code/RecommendedReader/database.py", line 62, in __del__
    self.__conn.close()
ProgrammingError: closing a closed connection

2013-08-27 22:12:12,234 - mylog - ERROR - Traceback (most recent call last):
  File "/home/asus/code/RecommendedReader/database.py", line 62, in __del__
    self.__conn.close()
ProgrammingError: closing a closed connection

2013-08-27 22:12:12,235 - mylog - ERROR - Traceback (most recent call last):
  File "/home/asus/code/RecommendedReader/server.py", line 71, in getDataToSend
    actionType = args[0]
TypeError: 'NoneType' object has no attribute '__getitem__'

2013-08-27 22:12:12,234 - mylog - ERROR - Traceback (most recent call last):
  File "/home/asus/code/RecommendedReader/database.py", line 62, in __del__
    self.__conn.close()
ProgrammingError: closing a closed connection

2013-08-27 22:12:12,235 - mylog - ERROR - Traceback (most recent call last):
  File "/home/asus/code/RecommendedReader/server.py", line 71, in getDataToSend
    actionType = args[0]
TypeError: 'NoneType' object has no attribute '__getitem__'

2013-08-27 22:12:12,235 - mylog - ERROR - Traceback (most recent call last):
  File "/home/asus/code/RecommendedReader/server.py", line 71, in getDataToSend
    actionType = args[0]
TypeError: 'NoneType' object has no attribute '__getitem__'

2013-08-27 22:12:12,235 - mylog - ERROR - Traceback (most recent call last):
  File "/home/asus/code/RecommendedReader/server.py", line 71, in getDataToSend
    actionType = args[0]
TypeError: 'NoneType' object has no attribute '__getitem__'

2013-08-27 22:12:12,237 - mylog - ERROR - Traceback (most recent call last):
  File "/home/asus/code/RecommendedReader/database.py", line 62, in __del__
    self.__conn.close()
ProgrammingError: closing a closed connection

2013-08-27 22:12:12,237 - mylog - ERROR - Traceback (most recent call last):
  File "/home/asus/code/RecommendedReader/database.py", line 62, in __del__
    self.__conn.close()
ProgrammingError: closing a closed connection

2013-08-27 22:12:12,237 - mylog - ERROR - Traceback (most recent call last):
  File "/home/asus/code/RecommendedReader/database.py", line 62, in __del__
    self.__conn.close()
ProgrammingError: closing a closed connection

2013-08-27 22:12:12,237 - mylog - ERROR - Traceback (most recent call last):
  File "/home/asus/code/RecommendedReader/database.py", line 62, in __del__
    self.__conn.close()
ProgrammingError: closing a closed connection

2013-08-27 22:12:12,237 - mylog - ERROR - Traceback (most recent call last):
  File "/home/asus/code/RecommendedReader/database.py", line 62, in __del__
    self.__conn.close()
ProgrammingError: closing a closed connection

2013-08-27 22:33:43,848 - mylog - ERROR - Traceback (most recent call last):
  File "/home/asus/code/RecommendedReader/socketServer.py", line 67, in getHeader
    clientJsonObj = json.loads(buf)
NameError: global name 'json' is not defined

2013-08-27 22:33:43,848 - mylog - ERROR - Traceback (most recent call last):
  File "/home/asus/code/RecommendedReader/socketServer.py", line 67, in getHeader
    clientJsonObj = json.loads(buf)
NameError: global name 'json' is not defined

2013-08-27 22:33:43,848 - mylog - ERROR - Traceback (most recent call last):
  File "/home/asus/code/RecommendedReader/socketServer.py", line 67, in getHeader
    clientJsonObj = json.loads(buf)
NameError: global name 'json' is not defined

2013-08-27 22:33:43,849 - mylog - ERROR - Traceback (most recent call last):
  File "/home/asus/code/RecommendedReader/socketServer.py", line 67, in getHeader
    clientJsonObj = json.loads(buf)
NameError: global name 'json' is not defined

2013-08-27 22:33:43,849 - mylog - ERROR - Traceback (most recent call last):
  File "/home/asus/code/RecommendedReader/socketServer.py", line 67, in getHeader
    clientJsonObj = json.loads(buf)
NameError: global name 'json' is not defined

2013-08-27 22:33:43,849 - mylog - ERROR - Traceback (most recent call last):
  File "/home/asus/code/RecommendedReader/socketServer.py", line 67, in getHeader
    clientJsonObj = json.loads(buf)
NameError: global name 'json' is not defined

2013-08-27 22:33:43,849 - mylog - ERROR - Traceback (most recent call last):
  File "/home/asus/code/RecommendedReader/socketServer.py", line 67, in getHeader
    clientJsonObj = json.loads(buf)
NameError: global name 'json' is not defined

2013-08-27 22:33:43,852 - mylog - ERROR - Traceback (most recent call last):
  File "/home/asus/code/RecommendedReader/server.py", line 90, in getDataToSend
    retmsg = checkAccount(mainAccount,mainPasswd)
NameError: global name 'checkAccount' is not defined

2013-08-27 22:33:43,852 - mylog - ERROR - Traceback (most recent call last):
  File "/home/asus/code/RecommendedReader/server.py", line 90, in getDataToSend
    retmsg = checkAccount(mainAccount,mainPasswd)
NameError: global name 'checkAccount' is not defined

2013-08-27 22:33:43,852 - mylog - ERROR - Traceback (most recent call last):
  File "/home/asus/code/RecommendedReader/server.py", line 90, in getDataToSend
    retmsg = checkAccount(mainAccount,mainPasswd)
NameError: global name 'checkAccount' is not defined

2013-08-27 22:33:43,852 - mylog - ERROR - Traceback (most recent call last):
  File "/home/asus/code/RecommendedReader/server.py", line 90, in getDataToSend
    retmsg = checkAccount(mainAccount,mainPasswd)
NameError: global name 'checkAccount' is not defined

2013-08-27 22:33:43,852 - mylog - ERROR - Traceback (most recent call last):
  File "/home/asus/code/RecommendedReader/server.py", line 90, in getDataToSend
    retmsg = checkAccount(mainAccount,mainPasswd)
NameError: global name 'checkAccount' is not defined

2013-08-27 22:33:43,851 - mylog - ERROR - Traceback (most recent call last):
  File "/home/asus/code/RecommendedReader/server.py", line 90, in getDataToSend
    retmsg = checkAccount(mainAccount,mainPasswd)
NameError: global name 'checkAccount' is not defined

2013-08-27 22:33:43,851 - mylog - ERROR - Traceback (most recent call last):
  File "/home/asus/code/RecommendedReader/server.py", line 90, in getDataToSend
    retmsg = checkAccount(mainAccount,mainPasswd)
NameError: global name 'checkAccount' is not defined

2013-08-27 22:33:43,851 - mylog - ERROR - Traceback (most recent call last):
  File "/home/asus/code/RecommendedReader/server.py", line 90, in getDataToSend
    retmsg = checkAccount(mainAccount,mainPasswd)
NameError: global name 'checkAccount' is not defined

2013-08-27 22:33:43,853 - mylog - ERROR - Traceback (most recent call last):
  File "/home/asus/code/RecommendedReader/database.py", line 62, in __del__
    self.__conn.close()
ProgrammingError: closing a closed connection

2013-08-27 22:33:43,851 - mylog - ERROR - Traceback (most recent call last):
  File "/home/asus/code/RecommendedReader/server.py", line 90, in getDataToSend
    retmsg = checkAccount(mainAccount,mainPasswd)
NameError: global name 'checkAccount' is not defined

2013-08-27 22:33:43,851 - mylog - ERROR - Traceback (most recent call last):
  File "/home/asus/code/RecommendedReader/server.py", line 90, in getDataToSend
    retmsg = checkAccount(mainAccount,mainPasswd)
NameError: global name 'checkAccount' is not defined

2013-08-27 22:33:43,853 - mylog - ERROR - Traceback (most recent call last):
  File "/home/asus/code/RecommendedReader/database.py", line 62, in __del__
    self.__conn.close()
ProgrammingError: closing a closed connection

2013-08-27 22:33:43,853 - mylog - ERROR - Traceback (most recent call last):
  File "/home/asus/code/RecommendedReader/database.py", line 62, in __del__
    self.__conn.close()
ProgrammingError: closing a closed connection

2013-08-27 22:33:43,851 - mylog - ERROR - Traceback (most recent call last):
  File "/home/asus/code/RecommendedReader/server.py", line 90, in getDataToSend
    retmsg = checkAccount(mainAccount,mainPasswd)
NameError: global name 'checkAccount' is not defined

2013-08-27 22:33:43,853 - mylog - ERROR - Traceback (most recent call last):
  File "/home/asus/code/RecommendedReader/database.py", line 62, in __del__
    self.__conn.close()
ProgrammingError: closing a closed connection

2013-08-27 22:33:43,853 - mylog - ERROR - Traceback (most recent call last):
  File "/home/asus/code/RecommendedReader/database.py", line 62, in __del__
    self.__conn.close()
ProgrammingError: closing a closed connection

2013-08-27 22:33:43,855 - mylog - ERROR - Traceback (most recent call last):
  File "/home/asus/code/RecommendedReader/database.py", line 62, in __del__
    self.__conn.close()
ProgrammingError: closing a closed connection

2013-08-27 22:33:43,853 - mylog - ERROR - Traceback (most recent call last):
  File "/home/asus/code/RecommendedReader/database.py", line 62, in __del__
    self.__conn.close()
ProgrammingError: closing a closed connection

2013-08-27 22:33:43,855 - mylog - ERROR - Traceback (most recent call last):
  File "/home/asus/code/RecommendedReader/database.py", line 62, in __del__
    self.__conn.close()
ProgrammingError: closing a closed connection

2013-08-27 22:33:43,855 - mylog - ERROR - Traceback (most recent call last):
  File "/home/asus/code/RecommendedReader/database.py", line 62, in __del__
    self.__conn.close()
ProgrammingError: closing a closed connection

2013-08-27 22:33:43,853 - mylog - ERROR - Traceback (most recent call last):
  File "/home/asus/code/RecommendedReader/database.py", line 62, in __del__
    self.__conn.close()
ProgrammingError: closing a closed connection

2013-08-27 22:33:43,855 - mylog - ERROR - Traceback (most recent call last):
  File "/home/asus/code/RecommendedReader/database.py", line 62, in __del__
    self.__conn.close()
ProgrammingError: closing a closed connection

2013-08-27 22:33:43,855 - mylog - ERROR - Traceback (most recent call last):
  File "/home/asus/code/RecommendedReader/database.py", line 62, in __del__
    self.__conn.close()
ProgrammingError: closing a closed connection

2013-08-27 22:33:43,855 - mylog - ERROR - Traceback (most recent call last):
  File "/home/asus/code/RecommendedReader/database.py", line 62, in __del__
    self.__conn.close()
ProgrammingError: closing a closed connection

2013-08-27 22:33:43,855 - mylog - ERROR - Traceback (most recent call last):
  File "/home/asus/code/RecommendedReader/database.py", line 62, in __del__
    self.__conn.close()
ProgrammingError: closing a closed connection

2013-08-27 22:51:16,683 - mylog - ERROR - Traceback (most recent call last):
  File "/home/asus/code/RecommendedReader/server.py", line 86, in getDataToSend
    retmsg = checkAccount(mainAccount,mainPasswd)
NameError: global name 'checkAccount' is not defined

2013-08-27 22:51:16,683 - mylog - ERROR - Traceback (most recent call last):
  File "/home/asus/code/RecommendedReader/server.py", line 86, in getDataToSend
    retmsg = checkAccount(mainAccount,mainPasswd)
NameError: global name 'checkAccount' is not defined

2013-08-27 22:51:16,683 - mylog - ERROR - Traceback (most recent call last):
  File "/home/asus/code/RecommendedReader/server.py", line 86, in getDataToSend
    retmsg = checkAccount(mainAccount,mainPasswd)
NameError: global name 'checkAccount' is not defined

2013-08-27 22:51:16,684 - mylog - ERROR - Traceback (most recent call last):
  File "/home/asus/code/RecommendedReader/server.py", line 76, in getDataToSend
    return register(mainAccount,mainPasswd)
NameError: global name 'register' is not defined

2013-08-27 22:51:16,685 - mylog - ERROR - Traceback (most recent call last):
  File "/home/asus/code/RecommendedReader/database.py", line 62, in __del__
    self.__conn.close()
ProgrammingError: closing a closed connection

2013-08-27 22:51:16,684 - mylog - ERROR - Traceback (most recent call last):
  File "/home/asus/code/RecommendedReader/server.py", line 76, in getDataToSend
    return register(mainAccount,mainPasswd)
NameError: global name 'register' is not defined

2013-08-27 22:51:16,684 - mylog - ERROR - Traceback (most recent call last):
  File "/home/asus/code/RecommendedReader/server.py", line 76, in getDataToSend
    return register(mainAccount,mainPasswd)
NameError: global name 'register' is not defined

2013-08-27 22:51:16,685 - mylog - ERROR - Traceback (most recent call last):
  File "/home/asus/code/RecommendedReader/database.py", line 62, in __del__
    self.__conn.close()
ProgrammingError: closing a closed connection

2013-08-27 22:51:16,684 - mylog - ERROR - Traceback (most recent call last):
  File "/home/asus/code/RecommendedReader/server.py", line 76, in getDataToSend
    return register(mainAccount,mainPasswd)
NameError: global name 'register' is not defined

2013-08-27 22:51:16,685 - mylog - ERROR - Traceback (most recent call last):
  File "/home/asus/code/RecommendedReader/database.py", line 62, in __del__
    self.__conn.close()
ProgrammingError: closing a closed connection

2013-08-27 22:51:16,687 - mylog - ERROR - Traceback (most recent call last):
  File "/home/asus/code/RecommendedReader/database.py", line 62, in __del__
    self.__conn.close()
ProgrammingError: closing a closed connection

2013-08-27 22:51:16,685 - mylog - ERROR - Traceback (most recent call last):
  File "/home/asus/code/RecommendedReader/database.py", line 62, in __del__
    self.__conn.close()
ProgrammingError: closing a closed connection

2013-08-27 22:51:16,687 - mylog - ERROR - Traceback (most recent call last):
  File "/home/asus/code/RecommendedReader/database.py", line 62, in __del__
    self.__conn.close()
ProgrammingError: closing a closed connection

2013-08-27 22:51:16,685 - mylog - ERROR - Traceback (most recent call last):
  File "/home/asus/code/RecommendedReader/database.py", line 62, in __del__
    self.__conn.close()
ProgrammingError: closing a closed connection

2013-08-27 22:51:16,687 - mylog - ERROR - Traceback (most recent call last):
  File "/home/asus/code/RecommendedReader/database.py", line 62, in __del__
    self.__conn.close()
ProgrammingError: closing a closed connection

2013-08-27 22:51:16,687 - mylog - ERROR - Traceback (most recent call last):
  File "/home/asus/code/RecommendedReader/database.py", line 62, in __del__
    self.__conn.close()
ProgrammingError: closing a closed connection

2013-08-27 22:51:16,687 - mylog - ERROR - Traceback (most recent call last):
  File "/home/asus/code/RecommendedReader/database.py", line 62, in __del__
    self.__conn.close()
ProgrammingError: closing a closed connection

2013-08-27 22:52:04,529 - mylog - ERROR - Traceback (most recent call last):
  File "/home/asus/code/RecommendedReader/socketServer.py", line 116, in startServer
    sock.bind(('localhost',port))
  File "/usr/lib/python2.7/socket.py", line 224, in meth
    return getattr(self._sock,name)(*args)
error: [Errno 98] Address already in use

2013-08-27 22:52:22,459 - mylog - ERROR - Traceback (most recent call last):
  File "/home/asus/code/RecommendedReader/server.py", line 86, in getDataToSend
    retmsg = self.checkAccount(mainAccount,mainPasswd)
UnboundLocalError: local variable 'mainAccount' referenced before assignment

2013-08-27 22:52:22,459 - mylog - ERROR - Traceback (most recent call last):
  File "/home/asus/code/RecommendedReader/server.py", line 86, in getDataToSend
    retmsg = self.checkAccount(mainAccount,mainPasswd)
UnboundLocalError: local variable 'mainAccount' referenced before assignment

2013-08-27 22:52:22,459 - mylog - ERROR - Traceback (most recent call last):
  File "/home/asus/code/RecommendedReader/server.py", line 86, in getDataToSend
    retmsg = self.checkAccount(mainAccount,mainPasswd)
UnboundLocalError: local variable 'mainAccount' referenced before assignment

2013-08-27 22:52:22,461 - mylog - ERROR - Traceback (most recent call last):
  File "/home/asus/code/RecommendedReader/server.py", line 76, in getDataToSend
    return register(mainAccount,mainPasswd)
NameError: global name 'register' is not defined

2013-08-27 22:52:22,461 - mylog - ERROR - Traceback (most recent call last):
  File "/home/asus/code/RecommendedReader/server.py", line 76, in getDataToSend
    return register(mainAccount,mainPasswd)
NameError: global name 'register' is not defined

2013-08-27 22:52:22,461 - mylog - ERROR - Traceback (most recent call last):
  File "/home/asus/code/RecommendedReader/server.py", line 76, in getDataToSend
    return register(mainAccount,mainPasswd)
NameError: global name 'register' is not defined

2013-08-27 22:52:22,461 - mylog - ERROR - Traceback (most recent call last):
  File "/home/asus/code/RecommendedReader/server.py", line 76, in getDataToSend
    return register(mainAccount,mainPasswd)
NameError: global name 'register' is not defined

2013-08-27 22:52:22,462 - mylog - ERROR - Traceback (most recent call last):
  File "/home/asus/code/RecommendedReader/database.py", line 62, in __del__
    self.__conn.close()
ProgrammingError: closing a closed connection

2013-08-27 22:52:22,462 - mylog - ERROR - Traceback (most recent call last):
  File "/home/asus/code/RecommendedReader/database.py", line 62, in __del__
    self.__conn.close()
ProgrammingError: closing a closed connection

2013-08-27 22:52:22,462 - mylog - ERROR - Traceback (most recent call last):
  File "/home/asus/code/RecommendedReader/database.py", line 62, in __del__
    self.__conn.close()
ProgrammingError: closing a closed connection

2013-08-27 22:52:22,462 - mylog - ERROR - Traceback (most recent call last):
  File "/home/asus/code/RecommendedReader/database.py", line 62, in __del__
    self.__conn.close()
ProgrammingError: closing a closed connection

2013-08-27 22:52:22,462 - mylog - ERROR - Traceback (most recent call last):
  File "/home/asus/code/RecommendedReader/database.py", line 62, in __del__
    self.__conn.close()
ProgrammingError: closing a closed connection

2013-08-27 22:52:22,463 - mylog - ERROR - Traceback (most recent call last):
  File "/home/asus/code/RecommendedReader/database.py", line 62, in __del__
    self.__conn.close()
ProgrammingError: closing a closed connection

2013-08-27 22:52:22,463 - mylog - ERROR - Traceback (most recent call last):
  File "/home/asus/code/RecommendedReader/database.py", line 62, in __del__
    self.__conn.close()
ProgrammingError: closing a closed connection

2013-08-27 22:52:22,463 - mylog - ERROR - Traceback (most recent call last):
  File "/home/asus/code/RecommendedReader/database.py", line 62, in __del__
    self.__conn.close()
ProgrammingError: closing a closed connection

2013-08-27 22:52:22,463 - mylog - ERROR - Traceback (most recent call last):
  File "/home/asus/code/RecommendedReader/database.py", line 62, in __del__
    self.__conn.close()
ProgrammingError: closing a closed connection

2013-08-27 22:52:22,463 - mylog - ERROR - Traceback (most recent call last):
  File "/home/asus/code/RecommendedReader/database.py", line 62, in __del__
    self.__conn.close()
ProgrammingError: closing a closed connection

2013-08-27 22:52:53,878 - mylog - ERROR - Traceback (most recent call last):
  File "/home/asus/code/RecommendedReader/socketServer.py", line 116, in startServer
    sock.bind(('localhost',port))
  File "/usr/lib/python2.7/socket.py", line 224, in meth
    return getattr(self._sock,name)(*args)
error: [Errno 98] Address already in use

2013-08-27 22:53:01,467 - mylog - ERROR - Traceback (most recent call last):
  File "/home/asus/code/RecommendedReader/socketServer.py", line 116, in startServer
    sock.bind(('localhost',port))
  File "/usr/lib/python2.7/socket.py", line 224, in meth
    return getattr(self._sock,name)(*args)
error: [Errno 98] Address already in use

2013-08-27 22:53:18,607 - mylog - ERROR - Traceback (most recent call last):
  File "/home/asus/code/RecommendedReader/socketServer.py", line 116, in startServer
    sock.bind(('localhost',port))
  File "/usr/lib/python2.7/socket.py", line 224, in meth
    return getattr(self._sock,name)(*args)
error: [Errno 98] Address already in use

2013-08-27 22:54:08,533 - mylog - ERROR - Traceback (most recent call last):
  File "/home/asus/code/RecommendedReader/server.py", line 86, in getDataToSend
    retmsg = self.checkAccount(mainAccount,mainPasswd)
UnboundLocalError: local variable 'mainAccount' referenced before assignment

2013-08-27 22:54:08,535 - mylog - ERROR - Traceback (most recent call last):
  File "/home/asus/code/RecommendedReader/server.py", line 76, in getDataToSend
    return self.register(mainAccount,mainPasswd)
  File "/home/asus/code/RecommendedReader/server.py", line 143, in register
    mainAcc = account.MainAccount(account,passwd)
AttributeError: 'unicode' object has no attribute 'MainAccount'

2013-08-27 22:54:08,533 - mylog - ERROR - Traceback (most recent call last):
  File "/home/asus/code/RecommendedReader/server.py", line 86, in getDataToSend
    retmsg = self.checkAccount(mainAccount,mainPasswd)
UnboundLocalError: local variable 'mainAccount' referenced before assignment

2013-08-27 22:54:08,535 - mylog - ERROR - Traceback (most recent call last):
  File "/home/asus/code/RecommendedReader/server.py", line 76, in getDataToSend
    return self.register(mainAccount,mainPasswd)
  File "/home/asus/code/RecommendedReader/server.py", line 143, in register
    mainAcc = account.MainAccount(account,passwd)
AttributeError: 'unicode' object has no attribute 'MainAccount'

2013-08-27 22:54:08,533 - mylog - ERROR - Traceback (most recent call last):
  File "/home/asus/code/RecommendedReader/server.py", line 86, in getDataToSend
    retmsg = self.checkAccount(mainAccount,mainPasswd)
UnboundLocalError: local variable 'mainAccount' referenced before assignment

2013-08-27 22:54:08,537 - mylog - ERROR - Traceback (most recent call last):
  File "/home/asus/code/RecommendedReader/database.py", line 62, in __del__
    self.__conn.close()
ProgrammingError: closing a closed connection

2013-08-27 22:54:08,537 - mylog - ERROR - Traceback (most recent call last):
  File "/home/asus/code/RecommendedReader/database.py", line 62, in __del__
    self.__conn.close()
ProgrammingError: closing a closed connection

2013-08-27 22:54:08,537 - mylog - ERROR - Traceback (most recent call last):
  File "/home/asus/code/RecommendedReader/database.py", line 62, in __del__
    self.__conn.close()
ProgrammingError: closing a closed connection

2013-08-27 22:54:08,537 - mylog - ERROR - Traceback (most recent call last):
  File "/home/asus/code/RecommendedReader/database.py", line 62, in __del__
    self.__conn.close()
ProgrammingError: closing a closed connection

2013-08-27 22:54:08,535 - mylog - ERROR - Traceback (most recent call last):
  File "/home/asus/code/RecommendedReader/server.py", line 76, in getDataToSend
    return self.register(mainAccount,mainPasswd)
  File "/home/asus/code/RecommendedReader/server.py", line 143, in register
    mainAcc = account.MainAccount(account,passwd)
AttributeError: 'unicode' object has no attribute 'MainAccount'

2013-08-27 22:54:08,535 - mylog - ERROR - Traceback (most recent call last):
  File "/home/asus/code/RecommendedReader/server.py", line 76, in getDataToSend
    return self.register(mainAccount,mainPasswd)
  File "/home/asus/code/RecommendedReader/server.py", line 143, in register
    mainAcc = account.MainAccount(account,passwd)
AttributeError: 'unicode' object has no attribute 'MainAccount'

2013-08-27 22:54:08,539 - mylog - ERROR - Traceback (most recent call last):
  File "/home/asus/code/RecommendedReader/database.py", line 62, in __del__
    self.__conn.close()
ProgrammingError: closing a closed connection

2013-08-27 22:54:08,539 - mylog - ERROR - Traceback (most recent call last):
  File "/home/asus/code/RecommendedReader/database.py", line 62, in __del__
    self.__conn.close()
ProgrammingError: closing a closed connection

2013-08-27 22:54:08,539 - mylog - ERROR - Traceback (most recent call last):
  File "/home/asus/code/RecommendedReader/database.py", line 62, in __del__
    self.__conn.close()
ProgrammingError: closing a closed connection

2013-08-27 22:54:08,539 - mylog - ERROR - Traceback (most recent call last):
  File "/home/asus/code/RecommendedReader/database.py", line 62, in __del__
    self.__conn.close()
ProgrammingError: closing a closed connection

2013-08-27 22:54:08,539 - mylog - ERROR - Traceback (most recent call last):
  File "/home/asus/code/RecommendedReader/database.py", line 62, in __del__
    self.__conn.close()
ProgrammingError: closing a closed connection

2013-08-27 22:55:51,282 - mylog - ERROR - Traceback (most recent call last):
  File "/home/asus/code/RecommendedReader/server.py", line 76, in getDataToSend
    return self.register(mainAccount,mainPasswd)
  File "/home/asus/code/RecommendedReader/server.py", line 143, in register
    mainAcc = account.MainAccount(account,passwd)
AttributeError: 'unicode' object has no attribute 'MainAccount'

2013-08-27 22:55:51,283 - mylog - ERROR - Traceback (most recent call last):
  File "/home/asus/code/RecommendedReader/server.py", line 86, in getDataToSend
    retmsg = self.checkAccount(mainAccount,mainPasswd)
UnboundLocalError: local variable 'mainAccount' referenced before assignment

2013-08-27 22:55:51,282 - mylog - ERROR - Traceback (most recent call last):
  File "/home/asus/code/RecommendedReader/server.py", line 76, in getDataToSend
    return self.register(mainAccount,mainPasswd)
  File "/home/asus/code/RecommendedReader/server.py", line 143, in register
    mainAcc = account.MainAccount(account,passwd)
AttributeError: 'unicode' object has no attribute 'MainAccount'

2013-08-27 22:55:51,282 - mylog - ERROR - Traceback (most recent call last):
  File "/home/asus/code/RecommendedReader/server.py", line 76, in getDataToSend
    return self.register(mainAccount,mainPasswd)
  File "/home/asus/code/RecommendedReader/server.py", line 143, in register
    mainAcc = account.MainAccount(account,passwd)
AttributeError: 'unicode' object has no attribute 'MainAccount'

2013-08-27 22:55:51,283 - mylog - ERROR - Traceback (most recent call last):
  File "/home/asus/code/RecommendedReader/server.py", line 86, in getDataToSend
    retmsg = self.checkAccount(mainAccount,mainPasswd)
UnboundLocalError: local variable 'mainAccount' referenced before assignment

2013-08-27 22:55:51,283 - mylog - ERROR - Traceback (most recent call last):
  File "/home/asus/code/RecommendedReader/server.py", line 86, in getDataToSend
    retmsg = self.checkAccount(mainAccount,mainPasswd)
UnboundLocalError: local variable 'mainAccount' referenced before assignment

2013-08-27 22:55:51,283 - mylog - ERROR - Traceback (most recent call last):
  File "/home/asus/code/RecommendedReader/server.py", line 86, in getDataToSend
    retmsg = self.checkAccount(mainAccount,mainPasswd)
UnboundLocalError: local variable 'mainAccount' referenced before assignment

2013-08-27 22:55:51,285 - mylog - ERROR - Traceback (most recent call last):
  File "/home/asus/code/RecommendedReader/database.py", line 62, in __del__
    self.__conn.close()
ProgrammingError: closing a closed connection

2013-08-27 22:55:51,285 - mylog - ERROR - Traceback (most recent call last):
  File "/home/asus/code/RecommendedReader/database.py", line 62, in __del__
    self.__conn.close()
ProgrammingError: closing a closed connection

2013-08-27 22:55:51,285 - mylog - ERROR - Traceback (most recent call last):
  File "/home/asus/code/RecommendedReader/database.py", line 62, in __del__
    self.__conn.close()
ProgrammingError: closing a closed connection

2013-08-27 22:55:51,285 - mylog - ERROR - Traceback (most recent call last):
  File "/home/asus/code/RecommendedReader/database.py", line 62, in __del__
    self.__conn.close()
ProgrammingError: closing a closed connection

2013-08-27 22:55:51,285 - mylog - ERROR - Traceback (most recent call last):
  File "/home/asus/code/RecommendedReader/database.py", line 62, in __del__
    self.__conn.close()
ProgrammingError: closing a closed connection

2013-08-27 22:55:51,285 - mylog - ERROR - Traceback (most recent call last):
  File "/home/asus/code/RecommendedReader/database.py", line 62, in __del__
    self.__conn.close()
ProgrammingError: closing a closed connection

2013-08-27 22:55:51,285 - mylog - ERROR - Traceback (most recent call last):
  File "/home/asus/code/RecommendedReader/database.py", line 62, in __del__
    self.__conn.close()
ProgrammingError: closing a closed connection

2013-08-27 22:55:51,285 - mylog - ERROR - Traceback (most recent call last):
  File "/home/asus/code/RecommendedReader/database.py", line 62, in __del__
    self.__conn.close()
ProgrammingError: closing a closed connection

2013-08-27 22:55:51,285 - mylog - ERROR - Traceback (most recent call last):
  File "/home/asus/code/RecommendedReader/database.py", line 62, in __del__
    self.__conn.close()
ProgrammingError: closing a closed connection

2013-08-27 22:55:51,285 - mylog - ERROR - Traceback (most recent call last):
  File "/home/asus/code/RecommendedReader/database.py", line 62, in __del__
    self.__conn.close()
ProgrammingError: closing a closed connection

2013-08-27 22:56:29,918 - mylog - ERROR - Traceback (most recent call last):
  File "/home/asus/code/RecommendedReader/server.py", line 86, in getDataToSend
    retmsg = self.checkAccount(mainAccount,mainPasswd)
UnboundLocalError: local variable 'mainAccount' referenced before assignment

2013-08-27 22:56:29,918 - mylog - ERROR - Traceback (most recent call last):
  File "/home/asus/code/RecommendedReader/server.py", line 86, in getDataToSend
    retmsg = self.checkAccount(mainAccount,mainPasswd)
UnboundLocalError: local variable 'mainAccount' referenced before assignment

2013-08-27 22:56:29,919 - mylog - ERROR - Traceback (most recent call last):
  File "/home/asus/code/RecommendedReader/database.py", line 62, in __del__
    self.__conn.close()
ProgrammingError: closing a closed connection

2013-08-27 22:56:29,919 - mylog - ERROR - Traceback (most recent call last):
  File "/home/asus/code/RecommendedReader/database.py", line 62, in __del__
    self.__conn.close()
ProgrammingError: closing a closed connection

2013-08-27 22:56:29,919 - mylog - ERROR - Traceback (most recent call last):
  File "/home/asus/code/RecommendedReader/database.py", line 62, in __del__
    self.__conn.close()
ProgrammingError: closing a closed connection

2013-08-27 22:56:29,943 - mylog - ERROR - Traceback (most recent call last):
  File "/home/asus/code/RecommendedReader/server.py", line 76, in getDataToSend
    return self.register(mainAccount,mainPasswd)
  File "/home/asus/code/RecommendedReader/server.py", line 143, in register
    mainAcc = acc.MainAccount(account,passwd)
  File "/home/asus/code/RecommendedReader/account.py", line 112, in __init__
    super(MainAccount).__init__(account,passwd)
TypeError: must be type, not unicode

2013-08-27 22:56:29,943 - mylog - ERROR - Traceback (most recent call last):
  File "/home/asus/code/RecommendedReader/server.py", line 76, in getDataToSend
    return self.register(mainAccount,mainPasswd)
  File "/home/asus/code/RecommendedReader/server.py", line 143, in register
    mainAcc = acc.MainAccount(account,passwd)
  File "/home/asus/code/RecommendedReader/account.py", line 112, in __init__
    super(MainAccount).__init__(account,passwd)
TypeError: must be type, not unicode

2013-08-27 22:56:29,943 - mylog - ERROR - Traceback (most recent call last):
  File "/home/asus/code/RecommendedReader/server.py", line 76, in getDataToSend
    return self.register(mainAccount,mainPasswd)
  File "/home/asus/code/RecommendedReader/server.py", line 143, in register
    mainAcc = acc.MainAccount(account,passwd)
  File "/home/asus/code/RecommendedReader/account.py", line 112, in __init__
    super(MainAccount).__init__(account,passwd)
TypeError: must be type, not unicode

2013-08-27 22:56:29,943 - mylog - ERROR - Traceback (most recent call last):
  File "/home/asus/code/RecommendedReader/server.py", line 76, in getDataToSend
    return self.register(mainAccount,mainPasswd)
  File "/home/asus/code/RecommendedReader/server.py", line 143, in register
    mainAcc = acc.MainAccount(account,passwd)
  File "/home/asus/code/RecommendedReader/account.py", line 112, in __init__
    super(MainAccount).__init__(account,passwd)
TypeError: must be type, not unicode

2013-08-27 22:56:29,944 - mylog - ERROR - Traceback (most recent call last):
  File "/home/asus/code/RecommendedReader/database.py", line 62, in __del__
    self.__conn.close()
ProgrammingError: closing a closed connection

2013-08-27 22:56:29,944 - mylog - ERROR - Traceback (most recent call last):
  File "/home/asus/code/RecommendedReader/database.py", line 62, in __del__
    self.__conn.close()
ProgrammingError: closing a closed connection

2013-08-27 22:56:29,944 - mylog - ERROR - Traceback (most recent call last):
  File "/home/asus/code/RecommendedReader/database.py", line 62, in __del__
    self.__conn.close()
ProgrammingError: closing a closed connection

2013-08-27 22:56:29,944 - mylog - ERROR - Traceback (most recent call last):
  File "/home/asus/code/RecommendedReader/database.py", line 62, in __del__
    self.__conn.close()
ProgrammingError: closing a closed connection

2013-08-27 22:56:29,944 - mylog - ERROR - Traceback (most recent call last):
  File "/home/asus/code/RecommendedReader/database.py", line 62, in __del__
    self.__conn.close()
ProgrammingError: closing a closed connection

2013-08-27 22:58:27,650 - mylog - ERROR - Traceback (most recent call last):
  File "/home/asus/code/RecommendedReader/server.py", line 91, in getDataToSend
    retmsg = self.checkAccount(mainAccount,mainPasswd)
  File "/home/asus/code/RecommendedReader/server.py", line 48, in checkAccount
    mainAcc = acc.MainAccount(mainAccount,mainPasswd)
NameError: global name 'mainAccount' is not defined

2013-08-27 22:58:27,650 - mylog - ERROR - Traceback (most recent call last):
  File "/home/asus/code/RecommendedReader/server.py", line 91, in getDataToSend
    retmsg = self.checkAccount(mainAccount,mainPasswd)
  File "/home/asus/code/RecommendedReader/server.py", line 48, in checkAccount
    mainAcc = acc.MainAccount(mainAccount,mainPasswd)
NameError: global name 'mainAccount' is not defined

2013-08-27 22:58:27,650 - mylog - ERROR - Traceback (most recent call last):
  File "/home/asus/code/RecommendedReader/server.py", line 91, in getDataToSend
    retmsg = self.checkAccount(mainAccount,mainPasswd)
  File "/home/asus/code/RecommendedReader/server.py", line 48, in checkAccount
    mainAcc = acc.MainAccount(mainAccount,mainPasswd)
NameError: global name 'mainAccount' is not defined

2013-08-27 22:58:27,652 - mylog - ERROR - Traceback (most recent call last):
  File "/home/asus/code/RecommendedReader/database.py", line 62, in __del__
    self.__conn.close()
ProgrammingError: closing a closed connection

2013-08-27 22:58:27,652 - mylog - ERROR - Traceback (most recent call last):
  File "/home/asus/code/RecommendedReader/database.py", line 62, in __del__
    self.__conn.close()
ProgrammingError: closing a closed connection

2013-08-27 22:58:27,652 - mylog - ERROR - Traceback (most recent call last):
  File "/home/asus/code/RecommendedReader/database.py", line 62, in __del__
    self.__conn.close()
ProgrammingError: closing a closed connection

2013-08-27 22:58:27,652 - mylog - ERROR - Traceback (most recent call last):
  File "/home/asus/code/RecommendedReader/database.py", line 62, in __del__
    self.__conn.close()
ProgrammingError: closing a closed connection

2013-08-27 22:58:27,651 - mylog - ERROR - Traceback (most recent call last):
  File "/home/asus/code/RecommendedReader/server.py", line 76, in getDataToSend
    return self.register(mainAccount,mainPasswd)
  File "/home/asus/code/RecommendedReader/server.py", line 148, in register
    mainAcc = acc.MainAccount(account,passwd)
  File "/home/asus/code/RecommendedReader/account.py", line 112, in __init__
    super(MainAccount).__init__(account,passwd)
TypeError: must be type, not unicode

2013-08-27 22:58:27,651 - mylog - ERROR - Traceback (most recent call last):
  File "/home/asus/code/RecommendedReader/server.py", line 76, in getDataToSend
    return self.register(mainAccount,mainPasswd)
  File "/home/asus/code/RecommendedReader/server.py", line 148, in register
    mainAcc = acc.MainAccount(account,passwd)
  File "/home/asus/code/RecommendedReader/account.py", line 112, in __init__
    super(MainAccount).__init__(account,passwd)
TypeError: must be type, not unicode

2013-08-27 22:58:27,651 - mylog - ERROR - Traceback (most recent call last):
  File "/home/asus/code/RecommendedReader/server.py", line 76, in getDataToSend
    return self.register(mainAccount,mainPasswd)
  File "/home/asus/code/RecommendedReader/server.py", line 148, in register
    mainAcc = acc.MainAccount(account,passwd)
  File "/home/asus/code/RecommendedReader/account.py", line 112, in __init__
    super(MainAccount).__init__(account,passwd)
TypeError: must be type, not unicode

2013-08-27 22:58:27,651 - mylog - ERROR - Traceback (most recent call last):
  File "/home/asus/code/RecommendedReader/server.py", line 76, in getDataToSend
    return self.register(mainAccount,mainPasswd)
  File "/home/asus/code/RecommendedReader/server.py", line 148, in register
    mainAcc = acc.MainAccount(account,passwd)
  File "/home/asus/code/RecommendedReader/account.py", line 112, in __init__
    super(MainAccount).__init__(account,passwd)
TypeError: must be type, not unicode

2013-08-27 22:58:27,654 - mylog - ERROR - Traceback (most recent call last):
  File "/home/asus/code/RecommendedReader/database.py", line 62, in __del__
    self.__conn.close()
ProgrammingError: closing a closed connection

2013-08-27 22:58:27,654 - mylog - ERROR - Traceback (most recent call last):
  File "/home/asus/code/RecommendedReader/database.py", line 62, in __del__
    self.__conn.close()
ProgrammingError: closing a closed connection

2013-08-27 22:58:27,654 - mylog - ERROR - Traceback (most recent call last):
  File "/home/asus/code/RecommendedReader/database.py", line 62, in __del__
    self.__conn.close()
ProgrammingError: closing a closed connection

2013-08-27 22:58:27,654 - mylog - ERROR - Traceback (most recent call last):
  File "/home/asus/code/RecommendedReader/database.py", line 62, in __del__
    self.__conn.close()
ProgrammingError: closing a closed connection

2013-08-27 22:58:27,654 - mylog - ERROR - Traceback (most recent call last):
  File "/home/asus/code/RecommendedReader/database.py", line 62, in __del__
    self.__conn.close()
ProgrammingError: closing a closed connection

2013-08-27 23:01:36,506 - mylog - ERROR - Traceback (most recent call last):
  File "/home/asus/code/RecommendedReader/server.py", line 94, in getDataToSend
    retmsg = self.checkAccount(mainAccount,mainPasswd)
  File "/home/asus/code/RecommendedReader/server.py", line 51, in checkAccount
    mainAcc = acc.MainAccount(account,passwd)
  File "/home/asus/code/RecommendedReader/account.py", line 112, in __init__
    super(MainAccount).__init__(account,passwd)
TypeError: must be type, not unicode

2013-08-27 23:01:36,506 - mylog - ERROR - Traceback (most recent call last):
  File "/home/asus/code/RecommendedReader/server.py", line 94, in getDataToSend
    retmsg = self.checkAccount(mainAccount,mainPasswd)
  File "/home/asus/code/RecommendedReader/server.py", line 51, in checkAccount
    mainAcc = acc.MainAccount(account,passwd)
  File "/home/asus/code/RecommendedReader/account.py", line 112, in __init__
    super(MainAccount).__init__(account,passwd)
TypeError: must be type, not unicode

2013-08-27 23:01:36,506 - mylog - ERROR - Traceback (most recent call last):
  File "/home/asus/code/RecommendedReader/server.py", line 79, in getDataToSend
    return self.register(mainAccount,mainPasswd)
  File "/home/asus/code/RecommendedReader/server.py", line 151, in register
    mainAcc = acc.MainAccount(account,passwd)
  File "/home/asus/code/RecommendedReader/account.py", line 112, in __init__
    super(MainAccount).__init__(account,passwd)
TypeError: must be type, not unicode

2013-08-27 23:01:36,506 - mylog - ERROR - Traceback (most recent call last):
  File "/home/asus/code/RecommendedReader/server.py", line 94, in getDataToSend
    retmsg = self.checkAccount(mainAccount,mainPasswd)
  File "/home/asus/code/RecommendedReader/server.py", line 51, in checkAccount
    mainAcc = acc.MainAccount(account,passwd)
  File "/home/asus/code/RecommendedReader/account.py", line 112, in __init__
    super(MainAccount).__init__(account,passwd)
TypeError: must be type, not unicode

2013-08-27 23:01:36,508 - mylog - ERROR - Traceback (most recent call last):
  File "/home/asus/code/RecommendedReader/database.py", line 62, in __del__
    self.__conn.close()
ProgrammingError: closing a closed connection

2013-08-27 23:01:36,506 - mylog - ERROR - Traceback (most recent call last):
  File "/home/asus/code/RecommendedReader/server.py", line 79, in getDataToSend
    return self.register(mainAccount,mainPasswd)
  File "/home/asus/code/RecommendedReader/server.py", line 151, in register
    mainAcc = acc.MainAccount(account,passwd)
  File "/home/asus/code/RecommendedReader/account.py", line 112, in __init__
    super(MainAccount).__init__(account,passwd)
TypeError: must be type, not unicode

2013-08-27 23:01:36,506 - mylog - ERROR - Traceback (most recent call last):
  File "/home/asus/code/RecommendedReader/server.py", line 79, in getDataToSend
    return self.register(mainAccount,mainPasswd)
  File "/home/asus/code/RecommendedReader/server.py", line 151, in register
    mainAcc = acc.MainAccount(account,passwd)
  File "/home/asus/code/RecommendedReader/account.py", line 112, in __init__
    super(MainAccount).__init__(account,passwd)
TypeError: must be type, not unicode

2013-08-27 23:01:36,508 - mylog - ERROR - Traceback (most recent call last):
  File "/home/asus/code/RecommendedReader/database.py", line 62, in __del__
    self.__conn.close()
ProgrammingError: closing a closed connection

2013-08-27 23:01:36,508 - mylog - ERROR - Traceback (most recent call last):
  File "/home/asus/code/RecommendedReader/database.py", line 62, in __del__
    self.__conn.close()
ProgrammingError: closing a closed connection

2013-08-27 23:01:36,506 - mylog - ERROR - Traceback (most recent call last):
  File "/home/asus/code/RecommendedReader/server.py", line 79, in getDataToSend
    return self.register(mainAccount,mainPasswd)
  File "/home/asus/code/RecommendedReader/server.py", line 151, in register
    mainAcc = acc.MainAccount(account,passwd)
  File "/home/asus/code/RecommendedReader/account.py", line 112, in __init__
    super(MainAccount).__init__(account,passwd)
TypeError: must be type, not unicode

2013-08-27 23:01:36,510 - mylog - ERROR - Traceback (most recent call last):
  File "/home/asus/code/RecommendedReader/database.py", line 62, in __del__
    self.__conn.close()
ProgrammingError: closing a closed connection

2013-08-27 23:01:36,508 - mylog - ERROR - Traceback (most recent call last):
  File "/home/asus/code/RecommendedReader/database.py", line 62, in __del__
    self.__conn.close()
ProgrammingError: closing a closed connection

2013-08-27 23:01:36,510 - mylog - ERROR - Traceback (most recent call last):
  File "/home/asus/code/RecommendedReader/database.py", line 62, in __del__
    self.__conn.close()
ProgrammingError: closing a closed connection

2013-08-27 23:01:36,510 - mylog - ERROR - Traceback (most recent call last):
  File "/home/asus/code/RecommendedReader/database.py", line 62, in __del__
    self.__conn.close()
ProgrammingError: closing a closed connection

2013-08-27 23:01:36,508 - mylog - ERROR - Traceback (most recent call last):
  File "/home/asus/code/RecommendedReader/database.py", line 62, in __del__
    self.__conn.close()
ProgrammingError: closing a closed connection

2013-08-27 23:01:36,510 - mylog - ERROR - Traceback (most recent call last):
  File "/home/asus/code/RecommendedReader/database.py", line 62, in __del__
    self.__conn.close()
ProgrammingError: closing a closed connection

2013-08-27 23:01:36,510 - mylog - ERROR - Traceback (most recent call last):
  File "/home/asus/code/RecommendedReader/database.py", line 62, in __del__
    self.__conn.close()
ProgrammingError: closing a closed connection

2013-08-27 23:03:55,002 - mylog - ERROR - Traceback (most recent call last):
  File "/home/asus/code/RecommendedReader/server.py", line 94, in getDataToSend
    retmsg = self.checkAccount(mainAccount,mainPasswd)
  File "/home/asus/code/RecommendedReader/server.py", line 51, in checkAccount
    mainAcc = acc.MainAccount(account,passwd)
  File "/home/asus/code/RecommendedReader/account.py", line 112, in __init__
    super(MainAccount).__init__(account,passwd)
TypeError: must be type, not unicode

2013-08-27 23:03:55,002 - mylog - ERROR - Traceback (most recent call last):
  File "/home/asus/code/RecommendedReader/server.py", line 94, in getDataToSend
    retmsg = self.checkAccount(mainAccount,mainPasswd)
  File "/home/asus/code/RecommendedReader/server.py", line 51, in checkAccount
    mainAcc = acc.MainAccount(account,passwd)
  File "/home/asus/code/RecommendedReader/account.py", line 112, in __init__
    super(MainAccount).__init__(account,passwd)
TypeError: must be type, not unicode

2013-08-27 23:03:55,002 - mylog - ERROR - Traceback (most recent call last):
  File "/home/asus/code/RecommendedReader/server.py", line 94, in getDataToSend
    retmsg = self.checkAccount(mainAccount,mainPasswd)
  File "/home/asus/code/RecommendedReader/server.py", line 51, in checkAccount
    mainAcc = acc.MainAccount(account,passwd)
  File "/home/asus/code/RecommendedReader/account.py", line 112, in __init__
    super(MainAccount).__init__(account,passwd)
TypeError: must be type, not unicode

2013-08-27 23:03:55,003 - mylog - ERROR - Traceback (most recent call last):
  File "/home/asus/code/RecommendedReader/database.py", line 62, in __del__
    self.__conn.close()
ProgrammingError: closing a closed connection

2013-08-27 23:03:55,003 - mylog - ERROR - Traceback (most recent call last):
  File "/home/asus/code/RecommendedReader/database.py", line 62, in __del__
    self.__conn.close()
ProgrammingError: closing a closed connection

2013-08-27 23:03:55,003 - mylog - ERROR - Traceback (most recent call last):
  File "/home/asus/code/RecommendedReader/database.py", line 62, in __del__
    self.__conn.close()
ProgrammingError: closing a closed connection

2013-08-27 23:03:55,003 - mylog - ERROR - Traceback (most recent call last):
  File "/home/asus/code/RecommendedReader/database.py", line 62, in __del__
    self.__conn.close()
ProgrammingError: closing a closed connection

2013-08-27 23:03:55,002 - mylog - ERROR - Traceback (most recent call last):
  File "/home/asus/code/RecommendedReader/server.py", line 79, in getDataToSend
    return self.register(mainAccount,mainPasswd)
  File "/home/asus/code/RecommendedReader/server.py", line 151, in register
    mainAcc = acc.MainAccount(account,passwd)
  File "/home/asus/code/RecommendedReader/account.py", line 112, in __init__
    super(MainAccount).__init__(account,passwd)
TypeError: must be type, not unicode

2013-08-27 23:03:55,002 - mylog - ERROR - Traceback (most recent call last):
  File "/home/asus/code/RecommendedReader/server.py", line 79, in getDataToSend
    return self.register(mainAccount,mainPasswd)
  File "/home/asus/code/RecommendedReader/server.py", line 151, in register
    mainAcc = acc.MainAccount(account,passwd)
  File "/home/asus/code/RecommendedReader/account.py", line 112, in __init__
    super(MainAccount).__init__(account,passwd)
TypeError: must be type, not unicode

2013-08-27 23:03:55,002 - mylog - ERROR - Traceback (most recent call last):
  File "/home/asus/code/RecommendedReader/server.py", line 79, in getDataToSend
    return self.register(mainAccount,mainPasswd)
  File "/home/asus/code/RecommendedReader/server.py", line 151, in register
    mainAcc = acc.MainAccount(account,passwd)
  File "/home/asus/code/RecommendedReader/account.py", line 112, in __init__
    super(MainAccount).__init__(account,passwd)
TypeError: must be type, not unicode

2013-08-27 23:03:55,002 - mylog - ERROR - Traceback (most recent call last):
  File "/home/asus/code/RecommendedReader/server.py", line 79, in getDataToSend
    return self.register(mainAccount,mainPasswd)
  File "/home/asus/code/RecommendedReader/server.py", line 151, in register
    mainAcc = acc.MainAccount(account,passwd)
  File "/home/asus/code/RecommendedReader/account.py", line 112, in __init__
    super(MainAccount).__init__(account,passwd)
TypeError: must be type, not unicode

2013-08-27 23:03:55,005 - mylog - ERROR - Traceback (most recent call last):
  File "/home/asus/code/RecommendedReader/database.py", line 62, in __del__
    self.__conn.close()
ProgrammingError: closing a closed connection

2013-08-27 23:03:55,005 - mylog - ERROR - Traceback (most recent call last):
  File "/home/asus/code/RecommendedReader/database.py", line 62, in __del__
    self.__conn.close()
ProgrammingError: closing a closed connection

2013-08-27 23:03:55,005 - mylog - ERROR - Traceback (most recent call last):
  File "/home/asus/code/RecommendedReader/database.py", line 62, in __del__
    self.__conn.close()
ProgrammingError: closing a closed connection

2013-08-27 23:03:55,005 - mylog - ERROR - Traceback (most recent call last):
  File "/home/asus/code/RecommendedReader/database.py", line 62, in __del__
    self.__conn.close()
ProgrammingError: closing a closed connection

2013-08-27 23:03:55,005 - mylog - ERROR - Traceback (most recent call last):
  File "/home/asus/code/RecommendedReader/database.py", line 62, in __del__
    self.__conn.close()
ProgrammingError: closing a closed connection

2013-08-27 23:05:16,243 - mylog - ERROR - Traceback (most recent call last):
  File "/home/asus/code/RecommendedReader/server.py", line 79, in getDataToSend
    return self.register(mainAccount,mainPasswd)
  File "/home/asus/code/RecommendedReader/server.py", line 151, in register
    mainAcc = acc.MainAccount(account,passwd)
  File "/home/asus/code/RecommendedReader/account.py", line 116, in __init__
    super(MainAccount).__init__(account,passwd)
TypeError: must be type, not unicode

2013-08-27 23:05:16,243 - mylog - ERROR - Traceback (most recent call last):
  File "/home/asus/code/RecommendedReader/server.py", line 79, in getDataToSend
    return self.register(mainAccount,mainPasswd)
  File "/home/asus/code/RecommendedReader/server.py", line 151, in register
    mainAcc = acc.MainAccount(account,passwd)
  File "/home/asus/code/RecommendedReader/account.py", line 116, in __init__
    super(MainAccount).__init__(account,passwd)
TypeError: must be type, not unicode

2013-08-27 23:05:16,244 - mylog - ERROR - Traceback (most recent call last):
  File "/home/asus/code/RecommendedReader/database.py", line 62, in __del__
    self.__conn.close()
ProgrammingError: closing a closed connection

2013-08-27 23:05:16,244 - mylog - ERROR - Traceback (most recent call last):
  File "/home/asus/code/RecommendedReader/database.py", line 62, in __del__
    self.__conn.close()
ProgrammingError: closing a closed connection

2013-08-27 23:05:16,244 - mylog - ERROR - Traceback (most recent call last):
  File "/home/asus/code/RecommendedReader/database.py", line 62, in __del__
    self.__conn.close()
ProgrammingError: closing a closed connection

2013-08-27 23:05:16,244 - mylog - ERROR - Traceback (most recent call last):
  File "/home/asus/code/RecommendedReader/database.py", line 62, in __del__
    self.__conn.close()
ProgrammingError: closing a closed connection

2013-08-27 23:05:16,245 - mylog - ERROR - Traceback (most recent call last):
  File "/home/asus/code/RecommendedReader/server.py", line 94, in getDataToSend
    retmsg = self.checkAccount(mainAccount,mainPasswd)
  File "/home/asus/code/RecommendedReader/server.py", line 51, in checkAccount
    mainAcc = acc.MainAccount(account,passwd)
  File "/home/asus/code/RecommendedReader/account.py", line 116, in __init__
    super(MainAccount).__init__(account,passwd)
TypeError: must be type, not unicode

2013-08-27 23:05:16,245 - mylog - ERROR - Traceback (most recent call last):
  File "/home/asus/code/RecommendedReader/server.py", line 94, in getDataToSend
    retmsg = self.checkAccount(mainAccount,mainPasswd)
  File "/home/asus/code/RecommendedReader/server.py", line 51, in checkAccount
    mainAcc = acc.MainAccount(account,passwd)
  File "/home/asus/code/RecommendedReader/account.py", line 116, in __init__
    super(MainAccount).__init__(account,passwd)
TypeError: must be type, not unicode

2013-08-27 23:05:16,245 - mylog - ERROR - Traceback (most recent call last):
  File "/home/asus/code/RecommendedReader/server.py", line 94, in getDataToSend
    retmsg = self.checkAccount(mainAccount,mainPasswd)
  File "/home/asus/code/RecommendedReader/server.py", line 51, in checkAccount
    mainAcc = acc.MainAccount(account,passwd)
  File "/home/asus/code/RecommendedReader/account.py", line 116, in __init__
    super(MainAccount).__init__(account,passwd)
TypeError: must be type, not unicode

2013-08-27 23:05:16,245 - mylog - ERROR - Traceback (most recent call last):
  File "/home/asus/code/RecommendedReader/server.py", line 94, in getDataToSend
    retmsg = self.checkAccount(mainAccount,mainPasswd)
  File "/home/asus/code/RecommendedReader/server.py", line 51, in checkAccount
    mainAcc = acc.MainAccount(account,passwd)
  File "/home/asus/code/RecommendedReader/account.py", line 116, in __init__
    super(MainAccount).__init__(account,passwd)
TypeError: must be type, not unicode

2013-08-27 23:05:16,247 - mylog - ERROR - Traceback (most recent call last):
  File "/home/asus/code/RecommendedReader/database.py", line 62, in __del__
    self.__conn.close()
ProgrammingError: closing a closed connection

2013-08-27 23:05:16,247 - mylog - ERROR - Traceback (most recent call last):
  File "/home/asus/code/RecommendedReader/database.py", line 62, in __del__
    self.__conn.close()
ProgrammingError: closing a closed connection

2013-08-27 23:05:16,247 - mylog - ERROR - Traceback (most recent call last):
  File "/home/asus/code/RecommendedReader/database.py", line 62, in __del__
    self.__conn.close()
ProgrammingError: closing a closed connection

2013-08-27 23:05:16,247 - mylog - ERROR - Traceback (most recent call last):
  File "/home/asus/code/RecommendedReader/database.py", line 62, in __del__
    self.__conn.close()
ProgrammingError: closing a closed connection

2013-08-27 23:05:16,247 - mylog - ERROR - Traceback (most recent call last):
  File "/home/asus/code/RecommendedReader/database.py", line 62, in __del__
    self.__conn.close()
ProgrammingError: closing a closed connection

2013-08-27 23:11:54,707 - mylog - ERROR - Traceback (most recent call last):
  File "/home/asus/code/RecommendedReader/server.py", line 79, in getDataToSend
    return self.register(mainAccount,mainPasswd)
  File "/home/asus/code/RecommendedReader/server.py", line 151, in register
    mainAcc = acc.MainAccount(account,passwd)
  File "/home/asus/code/RecommendedReader/account.py", line 119, in __init__
    super(MainAccount).__init__(account,passwd)
TypeError: must be type, not unicode

2013-08-27 23:11:54,707 - mylog - ERROR - Traceback (most recent call last):
  File "/home/asus/code/RecommendedReader/server.py", line 94, in getDataToSend
    retmsg = self.checkAccount(mainAccount,mainPasswd)
  File "/home/asus/code/RecommendedReader/server.py", line 51, in checkAccount
    mainAcc = acc.MainAccount(account,passwd)
  File "/home/asus/code/RecommendedReader/account.py", line 119, in __init__
    super(MainAccount).__init__(account,passwd)
TypeError: must be type, not unicode

2013-08-27 23:11:54,707 - mylog - ERROR - Traceback (most recent call last):
  File "/home/asus/code/RecommendedReader/server.py", line 79, in getDataToSend
    return self.register(mainAccount,mainPasswd)
  File "/home/asus/code/RecommendedReader/server.py", line 151, in register
    mainAcc = acc.MainAccount(account,passwd)
  File "/home/asus/code/RecommendedReader/account.py", line 119, in __init__
    super(MainAccount).__init__(account,passwd)
TypeError: must be type, not unicode

2013-08-27 23:11:54,707 - mylog - ERROR - Traceback (most recent call last):
  File "/home/asus/code/RecommendedReader/server.py", line 79, in getDataToSend
    return self.register(mainAccount,mainPasswd)
  File "/home/asus/code/RecommendedReader/server.py", line 151, in register
    mainAcc = acc.MainAccount(account,passwd)
  File "/home/asus/code/RecommendedReader/account.py", line 119, in __init__
    super(MainAccount).__init__(account,passwd)
TypeError: must be type, not unicode

2013-08-27 23:11:54,708 - mylog - ERROR - Traceback (most recent call last):
  File "/home/asus/code/RecommendedReader/database.py", line 62, in __del__
    self.__conn.close()
ProgrammingError: closing a closed connection

2013-08-27 23:11:54,707 - mylog - ERROR - Traceback (most recent call last):
  File "/home/asus/code/RecommendedReader/server.py", line 94, in getDataToSend
    retmsg = self.checkAccount(mainAccount,mainPasswd)
  File "/home/asus/code/RecommendedReader/server.py", line 51, in checkAccount
    mainAcc = acc.MainAccount(account,passwd)
  File "/home/asus/code/RecommendedReader/account.py", line 119, in __init__
    super(MainAccount).__init__(account,passwd)
TypeError: must be type, not unicode

2013-08-27 23:11:54,707 - mylog - ERROR - Traceback (most recent call last):
  File "/home/asus/code/RecommendedReader/server.py", line 94, in getDataToSend
    retmsg = self.checkAccount(mainAccount,mainPasswd)
  File "/home/asus/code/RecommendedReader/server.py", line 51, in checkAccount
    mainAcc = acc.MainAccount(account,passwd)
  File "/home/asus/code/RecommendedReader/account.py", line 119, in __init__
    super(MainAccount).__init__(account,passwd)
TypeError: must be type, not unicode

2013-08-27 23:11:54,707 - mylog - ERROR - Traceback (most recent call last):
  File "/home/asus/code/RecommendedReader/server.py", line 94, in getDataToSend
    retmsg = self.checkAccount(mainAccount,mainPasswd)
  File "/home/asus/code/RecommendedReader/server.py", line 51, in checkAccount
    mainAcc = acc.MainAccount(account,passwd)
  File "/home/asus/code/RecommendedReader/account.py", line 119, in __init__
    super(MainAccount).__init__(account,passwd)
TypeError: must be type, not unicode

2013-08-27 23:11:54,710 - mylog - ERROR - Traceback (most recent call last):
  File "/home/asus/code/RecommendedReader/database.py", line 62, in __del__
    self.__conn.close()
ProgrammingError: closing a closed connection

2013-08-27 23:11:54,708 - mylog - ERROR - Traceback (most recent call last):
  File "/home/asus/code/RecommendedReader/database.py", line 62, in __del__
    self.__conn.close()
ProgrammingError: closing a closed connection

2013-08-27 23:11:54,708 - mylog - ERROR - Traceback (most recent call last):
  File "/home/asus/code/RecommendedReader/database.py", line 62, in __del__
    self.__conn.close()
ProgrammingError: closing a closed connection

2013-08-27 23:11:54,710 - mylog - ERROR - Traceback (most recent call last):
  File "/home/asus/code/RecommendedReader/database.py", line 62, in __del__
    self.__conn.close()
ProgrammingError: closing a closed connection

2013-08-27 23:11:54,710 - mylog - ERROR - Traceback (most recent call last):
  File "/home/asus/code/RecommendedReader/database.py", line 62, in __del__
    self.__conn.close()
ProgrammingError: closing a closed connection

2013-08-27 23:11:54,710 - mylog - ERROR - Traceback (most recent call last):
  File "/home/asus/code/RecommendedReader/database.py", line 62, in __del__
    self.__conn.close()
ProgrammingError: closing a closed connection

2013-08-27 23:11:54,710 - mylog - ERROR - Traceback (most recent call last):
  File "/home/asus/code/RecommendedReader/database.py", line 62, in __del__
    self.__conn.close()
ProgrammingError: closing a closed connection

2013-08-27 23:11:54,708 - mylog - ERROR - Traceback (most recent call last):
  File "/home/asus/code/RecommendedReader/database.py", line 62, in __del__
    self.__conn.close()
ProgrammingError: closing a closed connection

2013-08-27 23:11:54,708 - mylog - ERROR - Traceback (most recent call last):
  File "/home/asus/code/RecommendedReader/database.py", line 62, in __del__
    self.__conn.close()
ProgrammingError: closing a closed connection

2013-08-27 23:13:05,018 - mylog - ERROR - Traceback (most recent call last):
  File "/home/asus/code/RecommendedReader/server.py", line 94, in getDataToSend
    retmsg = self.checkAccount(mainAccount,mainPasswd)
  File "/home/asus/code/RecommendedReader/server.py", line 51, in checkAccount
    mainAcc = acc.MainAccount(account,passwd)
  File "/home/asus/code/RecommendedReader/account.py", line 119, in __init__
    super(MainAccount).__init__(account,passwd)
TypeError: must be type, not unicode

2013-08-27 23:13:05,018 - mylog - ERROR - Traceback (most recent call last):
  File "/home/asus/code/RecommendedReader/server.py", line 94, in getDataToSend
    retmsg = self.checkAccount(mainAccount,mainPasswd)
  File "/home/asus/code/RecommendedReader/server.py", line 51, in checkAccount
    mainAcc = acc.MainAccount(account,passwd)
  File "/home/asus/code/RecommendedReader/account.py", line 119, in __init__
    super(MainAccount).__init__(account,passwd)
TypeError: must be type, not unicode

2013-08-27 23:13:05,018 - mylog - ERROR - Traceback (most recent call last):
  File "/home/asus/code/RecommendedReader/server.py", line 94, in getDataToSend
    retmsg = self.checkAccount(mainAccount,mainPasswd)
  File "/home/asus/code/RecommendedReader/server.py", line 51, in checkAccount
    mainAcc = acc.MainAccount(account,passwd)
  File "/home/asus/code/RecommendedReader/account.py", line 119, in __init__
    super(MainAccount).__init__(account,passwd)
TypeError: must be type, not unicode

2013-08-27 23:13:05,019 - mylog - ERROR - Traceback (most recent call last):
  File "/home/asus/code/RecommendedReader/database.py", line 62, in __del__
    self.__conn.close()
ProgrammingError: closing a closed connection

2013-08-27 23:13:05,019 - mylog - ERROR - Traceback (most recent call last):
  File "/home/asus/code/RecommendedReader/database.py", line 62, in __del__
    self.__conn.close()
ProgrammingError: closing a closed connection

2013-08-27 23:13:05,019 - mylog - ERROR - Traceback (most recent call last):
  File "/home/asus/code/RecommendedReader/database.py", line 62, in __del__
    self.__conn.close()
ProgrammingError: closing a closed connection

2013-08-27 23:13:05,019 - mylog - ERROR - Traceback (most recent call last):
  File "/home/asus/code/RecommendedReader/database.py", line 62, in __del__
    self.__conn.close()
ProgrammingError: closing a closed connection

2013-08-27 23:13:05,018 - mylog - ERROR - Traceback (most recent call last):
  File "/home/asus/code/RecommendedReader/server.py", line 79, in getDataToSend
    return self.register(mainAccount,mainPasswd)
  File "/home/asus/code/RecommendedReader/server.py", line 151, in register
    mainAcc = acc.MainAccount(account,passwd)
  File "/home/asus/code/RecommendedReader/account.py", line 119, in __init__
    super(MainAccount).__init__(account,passwd)
TypeError: must be type, not unicode

2013-08-27 23:13:05,018 - mylog - ERROR - Traceback (most recent call last):
  File "/home/asus/code/RecommendedReader/server.py", line 79, in getDataToSend
    return self.register(mainAccount,mainPasswd)
  File "/home/asus/code/RecommendedReader/server.py", line 151, in register
    mainAcc = acc.MainAccount(account,passwd)
  File "/home/asus/code/RecommendedReader/account.py", line 119, in __init__
    super(MainAccount).__init__(account,passwd)
TypeError: must be type, not unicode

2013-08-27 23:13:05,018 - mylog - ERROR - Traceback (most recent call last):
  File "/home/asus/code/RecommendedReader/server.py", line 79, in getDataToSend
    return self.register(mainAccount,mainPasswd)
  File "/home/asus/code/RecommendedReader/server.py", line 151, in register
    mainAcc = acc.MainAccount(account,passwd)
  File "/home/asus/code/RecommendedReader/account.py", line 119, in __init__
    super(MainAccount).__init__(account,passwd)
TypeError: must be type, not unicode

2013-08-27 23:13:05,018 - mylog - ERROR - Traceback (most recent call last):
  File "/home/asus/code/RecommendedReader/server.py", line 79, in getDataToSend
    return self.register(mainAccount,mainPasswd)
  File "/home/asus/code/RecommendedReader/server.py", line 151, in register
    mainAcc = acc.MainAccount(account,passwd)
  File "/home/asus/code/RecommendedReader/account.py", line 119, in __init__
    super(MainAccount).__init__(account,passwd)
TypeError: must be type, not unicode

2013-08-27 23:13:05,021 - mylog - ERROR - Traceback (most recent call last):
  File "/home/asus/code/RecommendedReader/database.py", line 62, in __del__
    self.__conn.close()
ProgrammingError: closing a closed connection

2013-08-27 23:13:05,021 - mylog - ERROR - Traceback (most recent call last):
  File "/home/asus/code/RecommendedReader/database.py", line 62, in __del__
    self.__conn.close()
ProgrammingError: closing a closed connection

2013-08-27 23:13:05,021 - mylog - ERROR - Traceback (most recent call last):
  File "/home/asus/code/RecommendedReader/database.py", line 62, in __del__
    self.__conn.close()
ProgrammingError: closing a closed connection

2013-08-27 23:13:05,021 - mylog - ERROR - Traceback (most recent call last):
  File "/home/asus/code/RecommendedReader/database.py", line 62, in __del__
    self.__conn.close()
ProgrammingError: closing a closed connection

2013-08-27 23:13:05,021 - mylog - ERROR - Traceback (most recent call last):
  File "/home/asus/code/RecommendedReader/database.py", line 62, in __del__
    self.__conn.close()
ProgrammingError: closing a closed connection

2013-08-27 23:20:20,432 - mylog - ERROR - Traceback (most recent call last):
  File "/home/asus/code/RecommendedReader/server.py", line 94, in getDataToSend
    retmsg = self.checkAccount(mainAccount,mainPasswd)
  File "/home/asus/code/RecommendedReader/server.py", line 52, in checkAccount
    ret = mainAcc.verify()
  File "/home/asus/code/RecommendedReader/account.py", line 123, in verify
    sql = "select * from MainAccounts where account = '%s' and password = '%s'" % (self.__account,self.__passwd)
AttributeError: 'MainAccount' object has no attribute '_MainAccount__account'

2013-08-27 23:20:20,432 - mylog - ERROR - Traceback (most recent call last):
  File "/home/asus/code/RecommendedReader/server.py", line 79, in getDataToSend
    return self.register(mainAccount,mainPasswd)
  File "/home/asus/code/RecommendedReader/server.py", line 152, in register
    retmsg = mainAcc.storeAccount()
TypeError: storeAccount() takes exactly 3 arguments (1 given)

2013-08-27 23:20:20,432 - mylog - ERROR - Traceback (most recent call last):
  File "/home/asus/code/RecommendedReader/server.py", line 94, in getDataToSend
    retmsg = self.checkAccount(mainAccount,mainPasswd)
  File "/home/asus/code/RecommendedReader/server.py", line 52, in checkAccount
    ret = mainAcc.verify()
  File "/home/asus/code/RecommendedReader/account.py", line 123, in verify
    sql = "select * from MainAccounts where account = '%s' and password = '%s'" % (self.__account,self.__passwd)
AttributeError: 'MainAccount' object has no attribute '_MainAccount__account'

2013-08-27 23:20:20,432 - mylog - ERROR - Traceback (most recent call last):
  File "/home/asus/code/RecommendedReader/server.py", line 94, in getDataToSend
    retmsg = self.checkAccount(mainAccount,mainPasswd)
  File "/home/asus/code/RecommendedReader/server.py", line 52, in checkAccount
    ret = mainAcc.verify()
  File "/home/asus/code/RecommendedReader/account.py", line 123, in verify
    sql = "select * from MainAccounts where account = '%s' and password = '%s'" % (self.__account,self.__passwd)
AttributeError: 'MainAccount' object has no attribute '_MainAccount__account'

2013-08-27 23:20:20,434 - mylog - ERROR - Traceback (most recent call last):
  File "/home/asus/code/RecommendedReader/database.py", line 62, in __del__
    self.__conn.close()
ProgrammingError: closing a closed connection

2013-08-27 23:20:20,434 - mylog - ERROR - Traceback (most recent call last):
  File "/home/asus/code/RecommendedReader/database.py", line 62, in __del__
    self.__conn.close()
ProgrammingError: closing a closed connection

2013-08-27 23:20:20,434 - mylog - ERROR - Traceback (most recent call last):
  File "/home/asus/code/RecommendedReader/database.py", line 62, in __del__
    self.__conn.close()
ProgrammingError: closing a closed connection

2013-08-27 23:20:20,434 - mylog - ERROR - Traceback (most recent call last):
  File "/home/asus/code/RecommendedReader/database.py", line 62, in __del__
    self.__conn.close()
ProgrammingError: closing a closed connection

2013-08-27 23:20:20,432 - mylog - ERROR - Traceback (most recent call last):
  File "/home/asus/code/RecommendedReader/server.py", line 79, in getDataToSend
    return self.register(mainAccount,mainPasswd)
  File "/home/asus/code/RecommendedReader/server.py", line 152, in register
    retmsg = mainAcc.storeAccount()
TypeError: storeAccount() takes exactly 3 arguments (1 given)

2013-08-27 23:20:20,432 - mylog - ERROR - Traceback (most recent call last):
  File "/home/asus/code/RecommendedReader/server.py", line 79, in getDataToSend
    return self.register(mainAccount,mainPasswd)
  File "/home/asus/code/RecommendedReader/server.py", line 152, in register
    retmsg = mainAcc.storeAccount()
TypeError: storeAccount() takes exactly 3 arguments (1 given)

2013-08-27 23:20:20,432 - mylog - ERROR - Traceback (most recent call last):
  File "/home/asus/code/RecommendedReader/server.py", line 79, in getDataToSend
    return self.register(mainAccount,mainPasswd)
  File "/home/asus/code/RecommendedReader/server.py", line 152, in register
    retmsg = mainAcc.storeAccount()
TypeError: storeAccount() takes exactly 3 arguments (1 given)

2013-08-27 23:20:20,436 - mylog - ERROR - Traceback (most recent call last):
  File "/home/asus/code/RecommendedReader/database.py", line 62, in __del__
    self.__conn.close()
ProgrammingError: closing a closed connection

2013-08-27 23:20:20,436 - mylog - ERROR - Traceback (most recent call last):
  File "/home/asus/code/RecommendedReader/database.py", line 62, in __del__
    self.__conn.close()
ProgrammingError: closing a closed connection

2013-08-27 23:20:20,436 - mylog - ERROR - Traceback (most recent call last):
  File "/home/asus/code/RecommendedReader/database.py", line 62, in __del__
    self.__conn.close()
ProgrammingError: closing a closed connection

2013-08-27 23:20:20,436 - mylog - ERROR - Traceback (most recent call last):
  File "/home/asus/code/RecommendedReader/database.py", line 62, in __del__
    self.__conn.close()
ProgrammingError: closing a closed connection

2013-08-27 23:20:20,436 - mylog - ERROR - Traceback (most recent call last):
  File "/home/asus/code/RecommendedReader/database.py", line 62, in __del__
    self.__conn.close()
ProgrammingError: closing a closed connection

